Workbook
Name \0: #REF!
Name \0: #REF!
Name \1: #REF!
Name \1: #REF!
Name \a: #REF!
Name \a: #REF!
Name \AA: #REF!
Name \b: #REF!
Name \C: #REF!
Name \d: #N/A
Name \e: #N/A
Name \f: #N/A
Name \g: #N/A
Name \H: #REF!
Name \H: #REF!
Name \i: #N/A
Name \j: #N/A
Name \k: #N/A
Name \KWS123: #N/A
Name \M: #REF!
Name \M: #REF!
Name \N: #REF!
Name \N: #REF!
Name \nbvf: #REF!
Name \P: #REF!
Name \P: #REF!
Name \R: #REF!
Name \R: #REF!
Name \s: #REF!
Name \s: #REF!
Name \t: #N/A
Name \U: #REF!
Name \V: #REF!
Name \x: #REF!
Name \x: #REF!
Name \z: #REF!
Name _: #REF!
Name _: #REF!
Name ____________________________________________________________________sw1: #REF!
Name ____________________________________________________________________sw1: #REF!
Name ____________________________________________________________________sw2: #REF!
Name ____________________________________________________________________sw2: #REF!
Name ____________________________________________________________________sw3: #REF!
Name ____________________________________________________________________sw3: #REF!
Name ____________________________________________________________________sw4: #REF!
Name ____________________________________________________________________sw5: #REF!
Name ____________________________________________________________________sw6: #REF!
Name ____________________________________________________________________sw7: #REF!
Name ____________________________________________________________________sw8: #REF!
Name ___________________________________________________________________sw1: #REF!
Name ___________________________________________________________________sw2: #REF!
Name ___________________________________________________________________sw3: #REF!
Name ___________________________________________________________________sw4: #REF!
Name ___________________________________________________________________sw5: #REF!
Name ___________________________________________________________________sw6: #REF!
Name ___________________________________________________________________sw7: #REF!
Name ___________________________________________________________________sw8: #REF!
Name __________________________________________________________________sw1: #REF!
Name __________________________________________________________________sw2: #REF!
Name __________________________________________________________________sw3: #REF!

Sheet Cover Page
C10: Bakreswar FSPV Financial Model- DPR

Sheet RA
A1: PVSyst File | L1: SolarGIS
B2: GlobHor | C2: DiffHor | D2: T_Amb | E2: GlobInc | F2: GlobEff | G2: EArray | H2: E_Grid
B3: kWh/m² | C3: kWh/m² | D3: °C | E3: kWh/m² | F3: kWh/m² | G3: MWh | H3: MWh | I3: PR | J3: Capacity (MW) | K3: Days | L3: CUF
A4: January | B4: 121.6 | C4: 63.7 | D4: 17.1 | E4: 129.4 | F4: 120.5 | G4: 26234 | H4: 24195 | I4: 0.767 | J4: 180.418 | K4: 31 | L4: =H4/J4/(24*K4) -> 0.18024898
A5: February | B5: 137.5 | C5: 61.8 | D5: 21 | E5: 144.6 | F5: 135.4 | G5: 29173 | H5: 28629 | I5: 0.812 | J5: =J4 -> 180.418 | K5: 28 | L5: =H5/J5/(24*K5) -> 0.23613319
A6: March | B6: 182.8 | C6: 77.6 | D6: 26.1 | E6: 188.7 | F6: 177.3 | G6: 37507 | H6: 36770 | I6: 0.799 | J6: =J5 -> 180.418 | K6: 31 | L6: =H6/J6/(24*K6) -> 0.27393078
A7: April | B7: 189.6 | C7: 87.2 | D7: 29.9 | E7: 191.9 | F7: 180.4 | G7: 37626 | H7: 36889 | I7: 0.788 | J7: =J6 -> 180.418 | K7: 30 | L7: =H7/J7/(24*K7) -> 0.28397789
A8: May | B8: 182.3 | C8: 101.1 | D8: 30.7 | E8: 181.9 | F8: 170.6 | G8: 35441 | H8: 34791 | I8: 0.784 | J8: =J7 -> 180.418 | K8: 31 | L8: =H8/J8/(24*K8) -> 0.25918754
A9: June | B9: 150.3 | C9: 95.4 | D9: 30.3 | E9: 149 | F9: 139.3 | G9: 28999 | H9: 28494 | I9: 0.784 | J9: =J8 -> 180.418 | K9: 30 | L9: =H9/J9/(24*K9) -> 0.21935173
A10: July | B10: 139.5 | C10: 91.3 | D10: 29.1 | E10: 138.7 | F10: 129.6 | G10: 27101 | H10: 26626 | I10: 0.787 | J10: =J9 -> 180.418 | K10: 31 | L10: =H10/J10/(24*K10) -> 0.19835956
A11: August | B11: 143.4 | C11: 89.7 | D11: 29 | E11: 143.9 | F11: 134.6 | G11: 28175 | H11: 27673 | I11: 0.789 | J11: =J10 -> 180.418 | K11: 31 | L11: =H11/J11/(24*K11) -> 0.20615954
A12: September | B12: 135.7 | C12: 80.1 | D12: 28.5 | E12: 137.9 | F12: 129.1 | G12: 27085 | H12: 26592 | I12: 0.79 | J12: =J11 -> 180.418 | K12: 30 | L12: =H12/J12/(24*K12) -> 0.2047098
A13: October | B13: 143.3 | C13: 73.6 | D13: 26.9 | E13: 148.8 | F13: 139.1 | G13: 29351 | H13: 28821 | I13: 0.794 | J13: =J12 -> 180.418 | K13: 31 | L13: =H13/J13/(24*K13) -> 0.21471196
A14: November | B14: 124.3 | C14: 64.9 | D14: 22.8 | E14: 131.5 | F14: 122.8 | G14: 26247 | H14: 22840 | I14: 0.712 | J14: =J13 -> 180.418 | K14: 30 | L14: =H14/J14/(24*K14) -> 0.17582626
A15: December | B15: 111.2 | C15: 62.5 | D15: 18.49 | E15: 118.3 | F15: 110.1 | G15: 23819 | H15: 21441 | I15: 0.743 | J15: =J14 -> 180.418 | K15: 31 | L15: =H15/J15/(24*K15) -> 0.15973211
A16: Year | B16: =SUM(B4:B15) -> 1761.5 | C16: =SUM(C4:C15) -> 948.9 | D16: 25.84 | E16: =SUM(E4:E15) -> 1804.6 | F16: =SUM(F4:F15) -> 1688.8 | G16: =SUM(G4:G15) -> 356758 | H16: =SUM(H4:H15) -> 343761 | I16: 0.781 | J16: =J15 -> 180.418 | K16: =SUM(K4:K15) -> 365 | L16: =H16/J16/(24*K16) -> 0.2175067
A18: Option 2
B19: GlobHor | C19: DiffHor | D19: T_Amb | E19: GlobInc | F19: GlobEff | G19: EArray | H19: E_Grid
B20: kWh/m² | C20: kWh/m² | D20: °C | E20: kWh/m² | F20: kWh/m² | G20: MWh | H20: MWh | I20: PR | J20: Capacity (MW) | K20: Days | L20: CUF
A21: January | B21: 121.6 | C21: 63.7 | D21: 17.1 | E21: 129.4 | F21: 120.5 | G21: 26662 | H21: 25367 | I21: 0.804 | J21: 199.6 | K21: 31 | L21: =H21/J21/(24*K21) -> 0.17081879
A22: February | B22: 137.5 | C22: 61.8 | D22: 21 | E22: 144.6 | F22: 135.4 | G22: 29646 | H22: 29198 | I22: 0.828 | J22: =J21 -> 199.6 | K22: 28 | L22: =H22/J22/(24*K22) -> 0.21768239
A23: March | B23: 182.8 | C23: 77.6 | D23: 26.1 | E23: 188.7 | F23: 177.3 | G23: 38108 | H23: 37512 | I23: 0.815 | J23: =J22 -> 199.6 | K23: 31 | L23: =H23/J23/(24*K23) -> 0.25260198
A24: April | B24: 189.6 | C24: 87.2 | D24: 29.9 | E24: 191.9 | F24: 180.4 | G24: 38230 | H24: 37634 | I24: 0.804 | J24: =J23 -> 199.6 | K24: 30 | L24: =H24/J24/(24*K24) -> 0.26187096
A25: May | B25: 182.3 | C25: 101.1 | D25: 30.7 | E25: 181.9 | F25: 170.6 | G25: 36021 | H25: 35482 | I25: 0.8 | J25: =J24 -> 199.6 | K25: 31 | L25: =H25/J25/(24*K25) -> 0.23893217
A26: June | B26: 150.3 | C26: 95.4 | D26: 30.3 | E26: 149 | F26: 139.3 | G26: 29471 | H26: 29042 | I26: 0.799 | J26: =J25 -> 199.6 | K26: 30 | L26: =H26/J26/(24*K26) -> 0.20208473
A27: July | B27: 139.5 | C27: 91.3 | D27: 29.1 | E27: 138.7 | F27: 129.6 | G27: 27533 | H27: 26983 | I27: 0.798 | J27: =J26 -> 199.6 | K27: 31 | L27: =H27/J27/(24*K27) -> 0.18170077
A28: August | B28: 143.4 | C28: 89.7 | D28: 29 | E28: 143.9 | F28: 134.6 | G28: 28631 | H28: 28209 | I28: 0.804 | J28: =J27 -> 199.6 | K28: 31 | L28: =H28/J28/(24*K28) -> 0.18995653
A29: September | B29: 135.7 | C29: 80.1 | D29: 28.5 | E29: 137.9 | F29: 129.1 | G29: 27520 | H29: 27107 | I29: 0.806 | J29: =J28 -> 199.6 | K29: 30 | L29: =H29/J29/(24*K29) -> 0.1886203
A30: October | B30: 143.3 | C30: 73.6 | D30: 26.9 | E30: 148.8 | F30: 139.1 | G30: 29829 | H30: 29384 | I30: 0.81 | J30: =J29 -> 199.6 | K30: 31 | L30: =H30/J30/(24*K30) -> 0.19786886
A31: November | B31: 124.3 | C31: 64.9 | D31: 22.8 | E31: 131.5 | F31: 122.8 | G31: 26672 | H31: 25980 | I31: 0.81 | J31: =J30 -> 199.6 | K31: 30 | L31: =H31/J31/(24*K31) -> 0.18077822
A32: December | B32: 111.2 | C32: 62.5 | D32: 18.49 | E32: 118.3 | F32: 110.1 | G32: 24207 | H32: 23859 | I32: 0.827 | J32: =J31 -> 199.6 | K32: 31 | L32: =H32/J32/(24*K32) -> 0.16066407
A33: Year | B33: =SUM(B21:B32) -> 1761.5 | C33: =SUM(C21:C32) -> 948.9 | D33: 25.84 | E33: =SUM(E21:E32) -> 1804.6 | F33: =SUM(F21:F32) -> 1688.8 | G33: 362529 | H33: 355757 | I33: 0.808 | J33: =J32 -> 199.6 | K33: =SUM(K21:K32) -> 365 | L33: =H33/J33/(24*K33) -> 0.20346458
A35: Option 2
B36: GlobHor | C36: DiffHor | D36: T_Amb | E36: GlobInc | F36: GlobEff | G36: EArray | H36: E_Grid
B37: kWh/m² | C37: kWh/m² | D37: °C | E37: kWh/m² | F37: kWh/m² | G37: MWh | H37: MWh | I37: PR | J37: Capacity (MW) | K37: Days | L37: CUF
A38: January | B38: 121.6 | C38: 63.7 | D38: 17.1 | E38: 129.4 | F38: 120.5 | G38: 26234 | H38: 24204 | I38: 0.767 | J38: 203.24 | K38: 31 | L38: =H38/J38/(24*K38) -> 0.16006819
A39: February | B39: 137.5 | C39: 61.8 | D39: 21 | E39: 144.6 | F39: 135.4 | G39: 29173 | H39: 28645 | I39: 0.812 | J39: =J38 -> 203.24 | K39: 28 | L39: =H39/J39/(24*K39) -> 0.20973474
A40: March | B40: 182.8 | C40: 77.6 | D40: 26.1 | E40: 188.7 | F40: 177.3 | G40: 37507 | H40: 36795 | I40: 0.8 | J40: =J39 -> 203.24 | K40: 31 | L40: =H40/J40/(24*K40) -> 0.24333618
A41: April | B41: 189.6 | C41: 87.2 | D41: 29.9 | E41: 191.9 | F41: 180.4 | G41: 37648 | H41: 36935 | I41: 0.789 | J41: =J40 -> 203.24 | K41: 30 | L41: =H42/J41/(24*K41) -> 0.23802592
A42: May | B42: 182.3 | C42: 101.1 | D42: 30.7 | E42: 181.9 | F42: 170.6 | G42: 35463 | H42: 34831 | I42: 0.785 | J42: =J41 -> 203.24 | K42: 31 | L42: =H43/J42/(24*K42) -> 0.18851197
...

Sheet Input
L1: Circularity
C2: Units | D2: Rate | E2: Quantity | I2: Levelized Tariff (Rs/ kWh) | J2: =Working!D276 -> 5.2535517 | L2: TRUE | M2: =L2 -> TRUE
B3: Technical | I3: FIRR | J3: =Working!D421 -> 0.087955957
B4: DC Capacity | C4: MWp | E4: =(D11*D15)+(E11*E15) -> 243.888 | I4: EIRR | J4: =Working!D482 -> 0.19492022 | L4: Option 2
B5: Conversion Factor | E5: =IF($F$5=$H$17,I17,I18) -> 1.2 | F5: Option 2 | I5: WACC | J5: =Input!$E$228 -> 0.07476 | L5: 705 | M5: 25% Overloading
B6: AC Capacity - Project | C6: MW | E6: =(D15*D12)+(E15*E12) -> 203.24 | I6: Rs.Crore/MW | J6: =Output!J6 -> 6.1137671
B7: CUF of the project | C7: % | E7: =RA!L50 -> 0.19317816 | I7: Rs.Crore/MWp | J7: =Output!I6 -> 5.0948059
B8: If Transmission Cost Included | C8: # | E8: Yes
B9: Water Depth- 73.5m | C9: # | E9: Yes | H9: Senstivity | I9: Change
D10: Island 1 | E10: Island 2 | H10: Project Cost | I10: 0
B11: Island unit capacity - DC | C11: MWp | D11: =6.087 -> 6.087 | E11: 4.092 | H11: CUF | I11: 0
B12: Island unit capacity - AC | C12: MW | D12: =D11/$E$5 -> 5.0725 | E12: =E11/$E$5 -> 3.41 | H12: Interest Rate | I12: 0
B13: Module Size | C13: Wp | D13: 580 | E13: 580 | H13: Overloading Factor | I13: =E5 -> 1.2
B14: Inverter size | C14: MW | D14: 4.4 | E14: 1.1
B15: No of islands | C15: # | D15: =IF($E$9="Yes",32,23) -> 32 | E15: =IF($E$9="Yes",12,15) -> 12
B16: No of Inverters | C16: # | D16: =D15+E15 -> 44 | E16: =E15 -> 12 | I16: Overloading
B17: No of Inverters per island | C17: # | D17: 1 | E17: 1 | H17: Option 1 | I17: 1.352
B18: No of modules per string | C18: # | D18: 28 | E18: 28 | H18: Option 2 | I18: 1.2
B20: Total Modules per island | C20: # | D20: =D22+D24 -> 336544 | E20: =E22+E24 -> 84841
B21: No of Module Floats per Sub Plot | C21: # | D21: 10496 | E21: 7056
B22: No of modules per island | C22: # | D22: =D15*D21 -> 335872 | E22: =E15*E21 -> 84672
B23: Spare Modules | C23: % | D23: 0.002 | E23: =D23 -> 0.002
B24: Spare Modules | C24: # | D24: =ROUND(D23*D22,0) -> 672 | E24: =ROUND(E23*E22,0) -> 169
B25: No of Main walkway Floats per Island | C25: # | D25: 1180 | E25: 856
B26: No of Long Secondary Float per Island | C26: # | D26: 4092 | E26: 2697
B27: No of Short Secondary Float per Island | C27: # | D27: 3712 | E27: 2436
B28: No of Secondary Walkway per Island | C28: # | D28: 597 | E28: 416
B29: No of Cable Float-DC | C29: # | D29: 20695 | E29: 7761
B30: No of Cable Float-AC | C30: # | D30: 24803 | E30: 9301
B31: Rigid Mooring Line | C31: KM | D31: =68320/1000 -> 68.32 | E31: =19320/1000 -> 19.32
B32: Flexible Mooring Line | C32: KM | D32: =55360/1000 -> 55.36 | E32: =15480/1000 -> 15.48
B33: Inverter Barge- Mooring Line | C33: KM | D33: =5940/1000 -> 5.94 | E33: =5940/1000 -> 5.94
A34: BOQ Assumptions | D34: Unit Rate | E34: No of Units
A35: A | B35: PV System
B36: PV Module | C36: # | D36: =14.4*1.1 -> 15.84 | E36: =IF($E$9="Yes",D20+E20,E36*0.95) -> 421385 | F36: 0
B37: EL Testing | C37: # | D37: 1000000 | E37: 1
B38: Thermography | C38: # | D38: 500000 | E38: 1
B39: Inverter 4.4 MW | C39: # | D39: 5700000 | E39: =D16 -> 44
B40: Inverter 1.1 MW | C40: # | D40: 1187500 | E40: =E16 -> 12
B42: Solar Project | H42: For 73.5 m | I42: For 72.5 m
...

Sheet BOQ_G
B1: Summary | C1: Unit | D1: Unit Costs | E1: Quantity | F1: Cost (Rs Lakh) | G1: Tax (Rs Lakh) | H1: Cost with Tax (Rs Lakh) | N1: Equipment Cost (Rs Lakhs) | O1: Installation Cost (Rs Lakhs) | P1: Total Cost (Rs per Wp) | Q1: Tax (Rs per Wp) | R1: Gross Cost (Rs per Wp) | S1: Cost (Rs Cr/ MW) | U1: Equipment Cost (Rs Lakhs) | V1: Installation Cost (Rs Lakhs) | W1: Total Cost (Rs Lakhs) | X1: Tax (Rs Lakhs) | Y1: Gross Cost (Rs Lakhs) | AA1: Equipment Cost | AB1: Installation Cost
A2: A | B2: PV Modules | C2: Lot | D2: =ROUND(F2/E2,0) -> 159 | E2: =Input!$E$4 -> 243.888 | F2: =SUM(F$36:F$39) -> 38728.483 | G2: =SUM(G$36:G$39) -> 5344.5306 | H2: =SUM(F2:G2) -> 44073.013 | N2: =ROUND($F2*$AA$2/Input!$E$4/10,2) -> 13.5 | O2: =ROUND($F2*(100%-$AA$2)/Input!$E$4/10,2) -> 2.38 | P2: =SUM(N2:O2) -> 15.88 | Q2: =N2*$AA$3+$O2*$AB$3 -> 2.0484 | R2: =P2+Q2 -> 17.9284 | S2: =H2/$E$27/100 -> 2.1685206 | U2: =F2*$AA$2 -> 32919.21 | V2: =F2*$AB$2 -> 4647.4179 | W2: =U2+V2 -> 37566.628 | X2: =G2 -> 5344.5306 | Y2: =H2 -> 44073.013 | AA2: 0.85 | AB2: 0.12
A3: B | B3: Inverters | C3: Lot | D3: =ROUND(F3/E3,0) -> 13 | E3: =Input!$E$6 -> 203.24 | F3: =SUM(F41:F42) -> 2650.5 | G3: =SUM(G41:G42) -> 365.769 | H3: =SUM(F3:G3) -> 3016.269 | N3: =ROUND($F3*$AA$2/Input!$E$4/10,2) -> 0.92 | O3: =ROUND($F3*(100%-$AA$2)/Input!$E$4/10,2) -> 0.16 | P3: =SUM(N3:O3) -> 1.08 | Q3: =N3*$AA$3+$O3*$AB$3 -> 0.1392 | R3: =P3+Q3 -> 1.2192 | S3: =H3/$E$27/100 -> 0.14840922 | U3: =F3*$AA$2 -> 2252.925 | V3: =F3*$AB$2 -> 318.06 | W3: =U3+V3 -> 2570.985 | X3: =G3 -> 365.769 | Y3: =H3 -> 3016.269 | AA3: =Input!F225 -> 0.12 | AB3: =Input!H225 -> 0.18
A4: C | B4: Floating Structures and Installation | C4: Lot | D4: =ROUND(F4/E4,0) -> 135 | E4: =Input!$E$4 -> 243.888 | F4: =SUM(F45:F60) -> 32929.861 | G4: =SUM(G45:G60) -> 4544.3208 | H4: =SUM(F4:G4) -> 37474.182 | N4: =ROUND($F4*$AA$2/Input!$E$4/10,2) -> 11.48 | O4: =ROUND($F4*(100%-$AA$2)/Input!$E$4/10,2) -> 2.03 | P4: =SUM(N4:O4) -> 13.51 | Q4: =N4*$AA$3+$O4*$AB$3 -> 1.743 | R4: =P4+Q4 -> 15.253 | S4: =H4/$E$27/100 -> 1.8438389 | U4: =F4*$AA$2 -> 27990.382 | V4: =F4*$AB$2 -> 3951.5833 | W4: =U4+V4 -> 31941.965 | X4: =G4 -> 4544.3208 | Y4: =H4 -> 37474.182 | AA4: =AA2*AA3+AB2*AB3 -> 0.1236
A5: 1 | B5: Float Structures | D5: =ROUND(F5/E5,0) -> 68 | E5: =Input!$E$4 -> 243.888 | F5: =SUM(F45:F51) -> 16470.638 | G5: =SUM(G45:G51) -> 2272.9481 | H5: =SUM(F5:G5) -> 18743.586 | N5: =ROUND($F5*$AA$2/Input!$E$4/10,2) -> 5.74 | O5: =ROUND($F5*(100%-$AA$2)/Input!$E$4/10,2) -> 1.01 | P5: =SUM(N5:O5) -> 6.75 | Q5: =ROUND(N5*$AA$3+$O5*$AB$3,2) -> 0.87 | R5: =P5+Q5 -> 7.62 | S5: =H5/$E$27/100 -> 0.92223905 | U5: =F5*$AA$2 -> 14000.043 | V5: =F5*$AB$2 -> 1976.4766 | W5: =U5+V5 -> 15976.519 | X5: =G5 -> 2272.9481 | Y5: =H5 -> 18743.586
A6: 2 | B6: Inverter Transformer System | D6: =ROUND(F6/E6,0) -> 25 | E6: =Input!$E$4 -> 243.888 | F6: =SUM(F53:F56) -> 6005.4825 | G6: =SUM(G53:G56) -> 828.75658 | H6: =SUM(F6:G6) -> 6834.239 | N6: =ROUND($F6*$AA$2/Input!$E$4/10,2) -> 2.09 | O6: =ROUND($F6*(100%-$AA$2)/Input!$E$4/10,2) -> 0.37 | P6: =SUM(N6:O6) -> 2.46 | Q6: =ROUND(N6*$AA$3+$O6*$AB$3,2) -> 0.32 | R6: =P6+Q6 -> 2.78 | S6: =H6/$E$27/100 -> 0.33626447 | U6: =F6*$AA$2 -> 5104.6601 | V6: =F6*$AB$2 -> 720.6579 | W6: =U6+V6 -> 5825.318 | X6: =G6 -> 828.75658 | Y6: =H6 -> 6834.239
A7: 3 | B7: Anchoring & Mooring | D7: =ROUND(F7/E7,0) -> 43 | E7: =Input!$E$4 -> 243.888 | F7: =SUM(F57:F60) -> 10453.74 | G7: =SUM(G57:G60) -> 1442.6161 | H7: =SUM(F7:G7) -> 11896.356 | N7: =ROUND($F7*$AA$2/Input!$E$4/10,2) -> 3.64 | O7: =ROUND($F7*(100%-$AA$2)/Input!$E$4/10,2) -> 0.64 | P7: =SUM(N7:O7) -> 4.28 | Q7: =ROUND(N7*$AA$3+$O7*$AB$3,2) -> 0.55 | R7: =P7+Q7 -> 4.83 | S7: =H7/$E$27/100 -> 0.58533537 | U7: =F7*$AA$2 -> 8885.679 | V7: =F7*$AB$2 -> 1254.4488 | W7: =U7+V7 -> 10140.128 | X7: =G7 -> 1442.6161 | Y7: =H7 -> 11896.356
A8: D | B8: Balance of System | C8: Lot | D8: =ROUND(F8/E8,0) -> 40 | E8: =Input!$E$4 -> 243.888 | F8: =SUM(F62:F193) -> 9694.1833 | G8: =SUM(G62:G193) -> 1337.7973 | H8: =SUM(F8:G8) -> 11031.981 | N8: =ROUND($F8*$AA$2/Input!$E$4/10,2) -> 3.38 | O8: =ROUND($F8*(100%-$AA$2)/Input!$E$4/10,2) -> 0.6 | P8: =SUM(N8:O8) -> 3.98 | Q8: =N8*$AA$3+$O8*$AB$3 -> 0.5136 | R8: =P8+Q8 -> 4.4936 | S8: =H8/$E$27/100 -> 0.54280558 | U8: =F8*$AA$2 -> 8240.0558 | V8: =F8*$AB$2 -> 1163.302 | W8: =U8+V8 -> 9403.3578 | X8: =G8 -> 1337.7973 | Y8: =H8 -> 11031.981
A9: 1 | B9: DC - Cables, SCB, Accessories | D9: =ROUND(F9/E9,0) -> 17 | E9: =Input!$E$4 -> 243.888 | F9: =SUM(F62:F80) -> 4077.46 | G9: =SUM(G62:G80) -> 562.68949 | H9: =SUM(F9:G9) -> 4640.1495 | N9: =ROUND($F9*$AA$2/Input!$E$4/10,2) -> 1.42 | O9: =ROUND($F9*(100%-$AA$2)/Input!$E$4/10,2) -> 0.25 | P9: =SUM(N9:O9) -> 1.67 | Q9: =N9*$AA$3+$O9*$AB$3 -> 0.2154 | R9: =P9+Q9 -> 1.8854 | S9: =H9/$E$27/100 -> 0.22830887 | U9: =F9*$AA$2 -> 3465.841 | V9: =F9*$AB$2 -> 489.2952 | W9: =U9+V9 -> 3955.1362 | X9: =G9 -> 562.68949 | Y9: =H9 -> 4640.1495
A10: 2 | B10: AC Cables | D10: =ROUND(F10/E10,0) -> 1 | E10: =Input!$E$4 -> 243.888 | F10: =SUM(F82:F112) -> 219.31885 | G10: =SUM(G82:G112) -> 30.266001 | H10: =SUM(F10:G10) -> 249.58485 | N10: =ROUND($F10*$AA$2/Input!$E$4/10,2) -> 0.08 | O10: =ROUND($F10*(100%-$AA$2)/Input!$E$4/10,2) -> 0.01 | P10: =SUM(N10:O10) -> 0.09 | Q10: =N10*$AA$3+$O10*$AB$3 -> 0.0114 | R10: =P10+Q10 -> 0.1014 | S10: =H10/$E$27/100 -> 0.012280302 | U10: =F10*$AA$2 -> 186.42102 | V10: =F10*$AB$2 -> 26.318262 | W10: =U10+V10 -> 212.73928 | X10: =G10 -> 30.266001 | Y10: =H10 -> 249.58485
A11: 3 | B11: Inverter Transformers, Switchgear and Panels | D11: =ROUND(F11/E11,0) -> 16 | E11: =Input!$E$4 -> 243.888 | F11: =SUM(F114:F154) -> 3922.9529 | G11: =SUM(G114:G154) -> 541.3675 | H11: =SUM(F11:G11) -> 4464.3204 | N11: =ROUND($F11*$AA$2/Input!$E$4/10,2) -> 1.37 | O11: =ROUND($F11*(100%-$AA$2)/Input!$E$4/10,2) -> 0.24 | P11: =SUM(N11:O11) -> 1.61 | Q11: =N11*$AA$3+$O11*$AB$3 -> 0.2076 | R11: =P11+Q11 -> 1.8176 | S11: =H11/$E$27/100 -> 0.21965757 | U11: =F11*$AA$2 -> 3334.51 | V11: =F11*$AB$2 -> 470.75435 | W11: =U11+V11 -> 3805.2643 | X11: =G11 -> 541.3675 | Y11: =H11 -> 4464.3204
A12: 4 | B12: Illumination System, Earthing | D12: =ROUND(F12/E12,0) -> 4 | E12: =Input!$E$4 -> 243.888 | F12: =SUM(F155:F177) -> 1034.4515 | G12: =SUM(G155:G177) -> 142.75431 | H12: =SUM(F12:G12) -> 1177.2058 | N12: =ROUND($F12*$AA$2/Input!$E$4/10,2) -> 0.36 | O12: =ROUND($F12*(100%-$AA$2)/Input!$E$4/10,2) -> 0.06 | P12: =SUM(N12:O12) -> 0.42 | Q12: =N12*$AA$3+$O12*$AB$3 -> 0.054 | R12: =P12+Q12 -> 0.474 | S12: =H12/$E$27/100 -> 0.057921955 | U12: =F12*$AA$2 -> 879.28379 | V12: =F12*$AB$2 -> 124.13418 | W12: =U12+V12 -> 1003.418 | X12: =G12 -> 142.75431 | Y12: =H12 -> 1177.2058
A13: 5 | B13: SCADA and Master Control Room | D13: =ROUND(F13/E13,0) -> 2 | E13: =Input!$E$4 -> 243.888 | F13: =SUM(F179:F193) -> 440 | G13: =SUM(G155:G164) -> 60.504101 | H13: =SUM(F13:G13) -> 500.5041 | N13: =ROUND($F13*$AA$2/Input!$E$4/10,2) -> 0.15 | O13: =ROUND($F13*(100%-$AA$2)/Input!$E$4/10,2) -> 0.03 | P13: =SUM(N13:O13) -> 0.18 | Q13: =N13*$AA$3+$O13*$AB$3 -> 0.0234 | R13: =P13+Q13 -> 0.2034 | S13: =H13/$E$27/100 -> 0.02462626 | U13: =F13*$AA$2 -> 374 | V13: =F13*$AB$2 -> 52.8 | W13: =U13+V13 -> 426.8 | X13: =G13 -> 60.504101 | Y13: =H13 -> 500.5041
A14: E | B14: Civil Infrastructure | C14: Lot | D14: =ROUND(F14/E14,0) -> 7 | E14: =Input!$E$4 -> 243.888 | F14: =SUM(F15:F17) -> 1663.1343 | G14: =SUM(G15:G17) -> 229.51254 | H14: =SUM(F14:G14) -> 1892.6469 | N14: =ROUND($F14*$AA$2/Input!$E$4/10,2) -> 0.58 | O14: =ROUND($F14*(100%-$AA$2)/Input!$E$4/10,2) -> 0.1 | P14: =SUM(N14:O14) -> 0.68 | Q14: =N14*$AA$3+$O14*$AB$3 -> 0.0876 | R14: =P14+Q14 -> 0.7676 | S14: =H14/$E$27/100 -> 0.093123738 | U14: =F14*$AA$2 -> 1413.6642 | V14: =F14*$AB$2 -> 199.57612 | W14: =U14+V14 -> 1613.2403 | X14: =G14 -> 229.51254 | Y14: =H14 -> 1892.6469
B15: Building and Civil Infrastructure | F15: =SUM(F196:F200) -> 308.13432 | G15: =SUM(G196:G200) -> 42.522536 | H15: =SUM(H196:H200) -> 350.65686 | N15: =ROUND($F15*$AA$2/Input!$E$4/10,2) -> 0.11 | O15: =ROUND($F15*(100%-$AA$2)/Input!$E$4/10,2) -> 0.02 | P15: =SUM(N15:O15) -> 0.13 | Q15: =N15*$AA$3+$O15*$AB$3 -> 0.0168 | R15: =P15+Q15 -> 0.1468 | S15: =H15/$E$27/100 -> 0.017253339 | U15: =F15*$AA$2 -> 261.91417 | V15: =F15*$AB$2 -> 36.976118 | W15: =U15+V15 -> 298.89029 | X15: =G15 -> 42.522536 | Y15: =H15 -> 350.65686
B16: Marine Infrastructure | F16: =SUM(F202:F204) -> 280 | G16: =SUM(G202:G204) -> 38.64 | H16: =SUM(H202:H204) -> 318.64 | N16: =ROUND($F16*$AA$2/Input!$E$4/10,2) -> 0.1 | O16: =ROUND($F16*(100%-$AA$2)/Input!$E$4/10,2) -> 0.02 | P16: =SUM(N16:O16) -> 0.12 | Q16: =N16*$AA$3+$O16*$AB$3 -> 0.0156 | R16: =P16+Q16 -> 0.1356 | S16: =H16/$E$27/100 -> 0.015678016 | U16: =F16*$AA$2 -> 238 | V16: =F16*$AB$2 -> 33.6 | W16: =U16+V16 -> 271.6 | X16: =G16 -> 38.64 | Y16: =H16 -> 318.64
B17: Other Infrastructure | F17: =SUM(F206:F214) -> 1075 | G17: =SUM(G206:G214) -> 148.35 | H17: =SUM(H206:H214) -> 1223.35 | N17: =ROUND($F17*$AA$2/Input!$E$4/10,2) -> 0.37 | O17: =ROUND($F17*(100%-$AA$2)/Input!$E$4/10,2) -> 0.07 | P17: =SUM(N17:O17) -> 0.44 | Q17: =N17*$AA$3+$O17*$AB$3 -> 0.057 | R17: =P17+Q17 -> 0.497 | S17: =H17/$E$27/100 -> 0.060192383 | U17: =F17*$AA$2 -> 913.75 | V17: =F17*$AB$2 -> 129 | W17: =U17+V17 -> 1042.75 | X17: =G17 -> 148.35 | Y17: =H17 -> 1223.35
B18: FSP Project Capital Cost | F18: =SUM(F2,F3,F4,F8,F14) -> 85666.161 | G18: =SUM(G2,G3,G4,G8,G14) -> 11821.93 | H18: =SUM(H2,H3,H4,H8,H14) -> 97488.091 | N18: =SUM(N2,N3,N4,N8,N14) -> 29.86 | O18: =SUM(O2,O3,O4,O8,O14) -> 5.27 | P18: =SUM(P2,P3,P4,P8,P14) -> 35.13 | Q18: =SUM(Q2,Q3,Q4,Q8,Q14) -> 4.5318 | R18: =SUM(R2,R3,R4,R8,R14) -> 39.6618 | S18: =H18/$E$27/100 -> 4.7966981 | U18: =F18*$AA$2 -> 72816.237 | V18: =F18*$AB$2 -> 10279.939 | W18: =U18+V18 -> 83096.176 | X18: =G18 -> 11821.93 | Y18: =H18 -> 97488.091
B19: Other Costs (Designs, Survey, Insurance, Warranty, etc) | F19: =SUM(F216:F220) -> 2941.3852 | G19: =SUM(G216:G220) -> 405.91116 | H19: =SUM(F19:G19) -> 3347.2964 | N19: =ROUND($F19*$AA$2/Input!$E$4/10,2) -> 1.03 | O19: =ROUND($F19*(100%-$AA$2)/Input!$E$4/10,2) -> 0.18 | P19: =SUM(N19:O19) -> 1.21 | Q19: =N19*$AA$3+$O19*$AB$3 -> 0.156 | R19: =P19+Q19 -> 1.366 | S19: =H19/$E$27/100 -> 0.16469673 | U19: =F19*$AA$2 -> 2500.1775 | V19: =F19*$AB$2 -> 352.96623 | W19: =U19+V19 -> 2853.1437 | X19: =G19 -> 405.91116 | Y19: =H19 -> 3347.2964
B20: Grand Total | F20: =F18+F19 -> 88607.546 | G20: =G18+G19 -> 12227.841 | H20: =SUM(F20:G20) -> 100835.39 | N20: =ROUND($F20*$AA$2/Input!$E$4/10,2) -> 30.88 | O20: =ROUND($F20*(100%-$AA$2)/Input!$E$4/10,2) -> 5.45 | P20: =SUM(N20:O20) -> 36.33 | Q20: =N20*$AA$3+$O20*$AB$3 -> 4.6866 | R20: =P20+Q20 -> 41.0166 | S20: =H20/$E$27/100 -> 4.9613948 | U20: =F20*$AA$2 -> 75316.414 | V20: =F20*$AB$2 -> 10632.906 | W20: =U20+V20 -> 85949.32 | X20: =G20 -> 12227.841 | Y20: =H20 -> 100835.39
B21: Profit Margin | F21: =F221 -> 6508.2021 | G21: =G221 -> 898.1319 | H21: =SUM(F21:G21) -> 7406.334 | N21: =ROUND($F21*$AA$2/Input!$E$4/10,2) -> 2.27 | O21: =ROUND($F21*(100%-$AA$2)/Input!$E$4/10,2) -> 0.4 | P21: =SUM(N21:O21) -> 2.67 | Q21: =N21*$AA$3+$O21*$AB$3 -> 0.3444 | R21: =P21+Q21 -> 3.0144 | S21: =H21/$E$27/100 -> 0.36441321 | U21: =F21*$AA$2 -> 5531.9718 | V21: =F21*$AB$2 -> 780.98426 | W21: =U21+V21 -> 6312.9561 | X21: =G21 -> 898.1319 | Y21: =H21 -> 7406.334
B22: FSPV Total | F22: =F20+F21 -> 95115.748 | G22: =G20+G21 -> 13125.973 | H22: =H20+H21 -> 108241.72 | N22: =N20+N21 -> 33.15 | O22: =O20+O21 -> 5.85 | P22: =P20+P21 -> 39 | Q22: =Q20+Q21 -> 5.031 | R22: =R20+R21 -> 44.031 | S22: =H22/$E$27/100 -> 5.325808 | U22: =F22*$AA$2 -> 80848.386 | V22: =F22*$AB$2 -> 11413.89 | W22: =U22+V22 -> 92262.276 | X22: =G22 -> 13125.973 | Y22: =H22 -> 108241.72
B23: Optional | F23: =SUM(F222:F227) -> 638.8 | G23: =SUM(G222:G227) -> 88.1544 | H23: =SUM(F23:G23) -> 726.9544 | N23: =ROUND($F23*$AA$2/Input!$E$4/10,2) -> 0.22 | O23: =ROUND($F23*(100%-$AA$2)/Input!$E$4/10,2) -> 0.04 | P23: =SUM(N23:O23) -> 0.26 | Q23: =N23*$AA$3+$O23*$AB$3 -> 0.0336 | R23: =P23+Q23 -> 0.2936 | S23: =H23/$E$27/100 -> 0.035768274 | U23: =F23*$AA$2 -> 542.98 | V23: =F23*$AB$2 -> 76.656 | W23: =U23+V23 -> 619.636 | X23: =G23 -> 88.1544 | Y23: =H23 -> 726.9544
Y24: =H24 -> 0
B25: General | E25: #
B26: Project Capacity | C26: MW DC | E26: =Input!E4 -> 243.888
B27: Project Capacity | C27: MW AC | E27: =Input!E6 -> 203.24
B28: Inverter Rating (in kW) & Qty (At 50ᵒ C Temp) | C28: 4400 | E28: =Input!D16 -> 44
B29: Inverter Rating (in kW) & Qty (At 50ᵒ C Temp) | C29: 1100 | E29: =Input!E16 -> 12
B30: Total Modules | C30: # | E30: =Input!E22+Input!D22 -> 420544
B31: Module rating | C31: Wp | E31: =Input!D13 -> 580
B32: # Module per string | C32: # | E32: =Input!D18 -> 28 | O32: =SUM(O36:O39)+(O41+O42)+SUM(O53:O56) -> 2.91
B34: BOQ | S34: Tax Rate
A35: A | B35: PV Modules
A36: 1 | B36: PV Modules | C36: # | D36: =Input!$D$36*$E$31 -> 9187.2 | E36: =Input!D22+Input!E22 -> 420544 | F36: =D36*E36/10^5 -> 38636.218 | G36: =$F36*$S36 -> 5331.7981 | H36: =F36+G36 -> 43968.017 | N36: =ROUND($F36*$AA$2/Input!$E$4/10,2) -> 13.47 | O36: =ROUND($F36*(100%-$AA$2)/Input!$E$4/10,2) -> 2.38 | P36: =SUM(N36:O36) -> 15.85 | Q36: =N36*$AA$3+$O36*$AB$3 -> 2.0448 | R36: =P36+Q36 -> 17.8948 | S36: 0.138 | U36: =F36*$AA$2 -> 32840.786 | V36: =F36*$AB$2 -> 4636.3462 | W36: =U36+V36 -> 37477.132 | X36: =G36 -> 5331.7981 | Y36: =H36 -> 43968.017
A37: 2 | B37: Spare Modules | C37: # | D37: =Input!$D$36*$E$31 -> 9187.2 | E37: =Input!D24+Input!E24 -> 841 | F37: =D37*E37/10^5 -> 77.264352 | G37: =$F37*$S37 -> 10.662481 | H37: =F37+G37 -> 87.926833 | N37: =ROUND($F37*$AA$2/Input!$E$4/10,2) -> 0.03 | O37: =ROUND($F37*(100%-$AA$2)/Input!$E$4/10,2) -> 0 | P37: =SUM(N37:O37) -> 0.03 | Q37: =N37*$AA$3+$O37*$AB$3 -> 0.0036 | R37: =P37+Q37 -> 0.0336 | S37: 0.138 | U37: =F37*$AA$2 -> 65.674699 | V37: =F37*$AB$2 -> 9.2717222 | W37: =U37+V37 -> 74.946421 | X37: =G37 -> 10.662481 | Y37: =H37 -> 87.926833
A38: 3 | B38: EL Testing | C38: # | D38: =Input!D37 -> 1000000 | E38: =Input!E37 -> 1 | F38: =D38*E38/10^5 -> 10 | G38: =$F38*$S38 -> 1.38 | H38: =F38+G38 -> 11.38 | N38: =ROUND($F38*$AA$2/Input!$E$4/10,2) -> 0 | O38: =ROUND($F38*(100%-$AA$2)/Input!$E$4/10,2) -> 0 | P38: =SUM(N38:O38) -> 0 | Q38: =N38*$AA$3+$O38*$AB$3 -> 0 | R38: =P38+Q38 -> 0 | S38: 0.138 | U38: =F38*$AA$2 -> 8.5 | V38: =F38*$AB$2 -> 1.2 | W38: =U38+V38 -> 9.7 | X38: =G38 -> 1.38 | Y38: =H38 -> 11.38
A39: 4 | B39: Thermography | C39: # | D39: =Input!D38 -> 500000 | E39: =Input!E38 -> 1 | F39: =D39*E39/10^5 -> 5 | G39: =$F39*$S39 -> 0.69 | H39: =F39+G39 -> 5.69 | N39: =ROUND($F39*$AA$2/Input!$E$4/10,2) -> 0 | O39: =ROUND($F39*(100%-$AA$2)/Input!$E$4/10,2) -> 0 | P39: =SUM(N39:O39) -> 0 | Q39: =N39*$AA$3+$O39*$AB$3 -> 0 | R39: =P39+Q39 -> 0 | S39: 0.138 | U39: =F39*$AA$2 -> 4.25 | V39: =F39*$AB$2 -> 0.6 | W39: =U39+V39 -> 4.85 | X39: =G39 -> 0.69 | Y39: =H39 -> 5.69
A40: B | B40: Inverters
A41: 1 | B41: Inverter 4.4 MW | C41: # | D41: =Input!D39 -> 5700000 | E41: =E28 -> 44 | F41: =D41*E41/10^5 -> 2508 | G41: =$F41*$S41 -> 346.104 | H41: =F41+G41 -> 2854.104 | N41: =ROUND($F41*$AA$2/Input!$E$4/10,2) -> 0.87 | O41: =ROUND($F41*(100%-$AA$2)/Input!$E$4/10,2) -> 0.15 | P41: =SUM(N41:O41) -> 1.02 | Q41: =N41*$AA$3+$O41*$AB$3 -> 0.1314 | R41: =P41+Q41 -> 1.1514 | S41: 0.138 | U41: =F41*$AA$2 -> 2131.8 | V41: =F41*$AB$2 -> 300.96 | W41: =U41+V41 -> 2432.76 | X41: =G41 -> 346.104 | Y41: =H41 -> 2854.104
...

Sheet BOQ_T
A1: Transmission Line and Sub-station
A2: Summary | B2: Particulars | C2: Unit Price | D2: Quantity | E2: Unit Rate (Rs Lakhs) | F2: Base Cost | G2: Tax | H2: Lumpsum Cost
B3: Pooling Sub-Station - 300 MW, 33/220 KV | F3: INR Lakhs | G3: INR Lakhs | H3: INR Lakhs | J3: Equipment Cost | K3: Installation Cost | L3: Base Cost
A4: 1 | B4: 33/220 kV, 80 MVA Power Transformer | C4: Lakhs/# | D4: =Input!D151 -> 4 | E4: =$F114/$D4 -> 1321.984 | F4: =D4*E4 -> 5287.936 | G4: =F4*Input!$D$167 -> 951.82848 | H4: =F4+G4 -> 6239.7645 | J4: =F4*BOQ_G!$AA$2 -> 4494.7456 | K4: =F4*BOQ_G!$AB$2 -> 634.55232 | L4: =SUM(J4:K4) -> 5129.2979
A5: 2 | B5: 33kV Incomer Feeder Bays (25MW) to 33 kV Bus | C5: Lakhs/# | D5: =Input!D152 -> 12 | E5: =SUM($F116:$F127)/$D5 -> 20.534 | F5: =D5*E5 -> 246.408 | G5: =F5*Input!$D$167 -> 44.35344 | H5: =F5+G5 -> 290.76144 | J5: =F5*BOQ_G!$AA$2 -> 209.4468 | K5: =F5*BOQ_G!$AB$2 -> 29.56896 | L5: =SUM(J5:K5) -> 239.01576
A6: 3 | B6: 33 kV Bus Section & Bus Coupler Bays | C6: Lakhs/# | D6: =Input!D153 -> 8 | E6: =SUM($F130:$F136)/$D6 -> 13.023125 | F6: =D6*E6 -> 104.185 | G6: =F6*Input!$D$167 -> 18.7533 | H6: =F6+G6 -> 122.9383 | J6: =F6*BOQ_G!$AA$2 -> 88.55725 | K6: =F6*BOQ_G!$AB$2 -> 12.5022 | L6: =SUM(J6:K6) -> 101.05945
A7: 4 | B7: 33kV incoming feeders for Power transformer | C7: Lakhs/# | D7: =Input!D154 -> 4 | E7: =SUM(F139,F141,F143,F145)/$D7 -> 19.83 | F7: =D7*E7 -> 79.32 | G7: =F7*Input!$D$167 -> 14.2776 | H7: =F7+G7 -> 93.5976 | J7: =F7*BOQ_G!$AA$2 -> 67.422 | K7: =F7*BOQ_G!$AB$2 -> 9.5184 | L7: =SUM(J7:K7) -> 76.9404
A8: 5 | B8: Reactive Power Compensation as per CEA connectivity standard, | C8: Lakhs/MVAr | D8: =Input!D155 -> 60 | E8: =SUM(F149,F151,F153,F155,F157)/$D8 -> 20.5915 | F8: =D8*E8 -> 1235.49 | G8: =F8*Input!$D$167 -> 222.3882 | H8: =F8+G8 -> 1457.8782 | J8: =F8*BOQ_G!$AA$2 -> 1050.1665 | K8: =F8*BOQ_G!$AB$2 -> 148.2588 | L8: =SUM(J8:K8) -> 1198.4253
A9: 6 | B9: 220kV Power Transformer Bay | C9: Lakhs/# | D9: =Input!D156 -> 4 | E9: =SUM(F160,F162,F164,F166,F168)/SUM($D$9:$D$11) -> 41.548 | F9: =D9*E9 -> 166.192 | G9: =F9*Input!$D$167 -> 29.91456 | H9: =F9+G9 -> 196.10656 | J9: =F9*BOQ_G!$AA$2 -> 141.2632 | K9: =F9*BOQ_G!$AB$2 -> 19.94304 | L9: =SUM(J9:K9) -> 161.20624
A10: 7 | B10: 220 kV Line Bay+ Bus Coupler Bay | C10: Lakhs/# | D10: =Input!D157 -> 3 | E10: =SUM(F160,F162,F164,F166,F168)/SUM($D$9:$D$11) -> 41.548 | F10: =D10*E10 -> 124.644 | G10: =F10*Input!$D$167 -> 22.43592 | H10: =F10+G10 -> 147.07992 | J10: =F10*BOQ_G!$AA$2 -> 105.9474 | K10: =F10*BOQ_G!$AB$2 -> 14.95728 | L10: =SUM(J10:K10) -> 120.90468
A11: 8 | B11: 220 kV Bus Transfer Bay | C11: Lakhs/# | D11: =Input!D158 -> 1 | E11: =SUM(F160,F162,F164,F166,F168)/SUM($D$9:$D$11) -> 41.548 | F11: =D11*E11 -> 41.548 | G11: =F11*Input!$D$167 -> 7.47864 | H11: =F11+G11 -> 49.02664 | J11: =F11*BOQ_G!$AA$2 -> 35.3158 | K11: =F11*BOQ_G!$AB$2 -> 4.98576 | L11: =SUM(J11:K11) -> 40.30156
A12: 9 | B12: Control & Communication | C12: Lakhs/# | D12: =Input!D159 -> 1 | E12: =SUM(F171,F173,F175,F177:F181,F183:F184)/$D12 -> 408.01 | F12: =D12*E12 -> 408.01 | G12: =F12*Input!$D$167 -> 73.4418 | H12: =F12+G12 -> 481.4518 | J12: =F12*BOQ_G!$AA$2 -> 346.8085 | K12: =F12*BOQ_G!$AB$2 -> 48.9612 | L12: =SUM(J12:K12) -> 395.7697
A13: A | B13: Pooling Sub-station | C13: MVA | D13: 320 | E13: =IF(Input!$E$8="Yes",F13/D13,0) -> 24.042916 | F13: =IF(Input!$E$8="Yes",SUM(F4:F12),"") -> 7693.733 | G13: =IF(Input!$E$8="Yes",SUM(G4:G12),"") -> 1384.8719 | H13: =IF(Input!$E$8="Yes",SUM(H4:H12),"") -> 9078.6049 | J13: =SUM(J4:J12) -> 6539.673 | K13: =SUM(K4:K12) -> 923.24796 | L13: =SUM(J13:K13) -> 7462.921
B14: Transmission Line
B15: Transmission Line Supply of Material as per specifications
A16: 1 | B16: Supply of 220kV Towers including fasteners | C16: Lakhs/Lot | D16: =Input!$D$118 -> 4 | F16: =SUM(F45:F48) -> 165.32793 | G16: =F16*Input!$E$167 -> 29.759027 | H16: =F16+G16 -> 195.08695 | J16: =F16*BOQ_G!$AA$2 -> 140.52874 | K16: =F16*BOQ_G!$AB$2 -> 19.839351 | L16: =SUM(J16:K16) -> 160.36809
A17: 2 | B17: ACCC Conductor, Earthwire Conductor & Accessories | C17: Lakhs/Lot | D17: =Input!$D$118 -> 4 | F17: =SUM(F51,F53,F56:F65) -> 481.4585 | G17: =F17*Input!$E$167 -> 86.66253 | H17: =F17+G17 -> 568.12103 | J17: =F17*BOQ_G!$AA$2 -> 409.23973 | K17: =F17*BOQ_G!$AB$2 -> 57.77502 | L17: =SUM(J17:K17) -> 467.01475
A18: 3 | B18: 220 KV Insulator with Stringing Accessories | C18: Lakhs/Lot | D18: =Input!$D$118 -> 4 | F18: =SUM(F68) -> 15.8712 | G18: =F18*Input!$E$167 -> 2.856816 | H18: =F18+G18 -> 18.728016 | J18: =F18*BOQ_G!$AA$2 -> 13.49052 | K18: =F18*BOQ_G!$AB$2 -> 1.904544 | L18: =SUM(J18:K18) -> 15.395064
A19: 4 | B19: 220kV Tower Earthing | C19: Lakhs/Lot | D19: =Input!$D$118 -> 4 | F19: =F70 -> 1.6128 | G19: =F19*Input!$E$167 -> 0.290304 | H19: =F19+G19 -> 1.903104 | J19: =F19*BOQ_G!$AA$2 -> 1.37088 | K19: =F19*BOQ_G!$AB$2 -> 0.193536 | L19: =SUM(J19:K19) -> 1.564416
A20: 5 | B20: 220kV Tower Accessories | C20: Lakhs/Lot | D20: =Input!$D$118 -> 4 | F20: =SUM(F72:F81) -> 1.5394285 | G20: =F20*Input!$E$167 -> 0.27709713 | H20: =F20+G20 -> 1.8165256 | J20: =F20*BOQ_G!$AA$2 -> 1.3085142 | K20: =F20*BOQ_G!$AB$2 -> 0.18473142 | L20: =SUM(J20:K20) -> 1.4932456
B21: Transmission Line Services & Erection Activities
A22: 1 | B22: Survey and Field Assessment | C22: Lakhs/Lot | F22: =SUM(F84:F86) -> 2.232 | G22: =F22*Input!$E$167 -> 0.40176 | H22: =F22+G22 -> 2.63376 | J22: =F22*BOQ_G!$AA$2 -> 1.8972 | K22: =F22*BOQ_G!$AB$2 -> 0.26784 | L22: =SUM(J22:K22) -> 2.16504
A23: 2 | B23: Tower Foundation and Errection | C23: Lakhs/Lot | F23: =SUM(F88:F94) -> 160.01381 | G23: =F23*Input!$E$167 -> 28.802485 | H23: =F23+G23 -> 188.81629 | J23: =F23*BOQ_G!$AA$2 -> 136.01174 | K23: =F23*BOQ_G!$AB$2 -> 19.201657 | L23: =SUM(J23:K23) -> 155.21339
A24: 3 | B24: Mounting of Insulators and Stringing | C24: Lakhs/Lot | F24: =F96+F97 -> 31.76 | G24: =F24*Input!$E$167 -> 5.7168 | H24: =F24+G24 -> 37.4768 | J24: =F24*BOQ_G!$AA$2 -> 26.996 | K24: =F24*BOQ_G!$AB$2 -> 3.8112 | L24: =SUM(J24:K24) -> 30.8072
A25: 4 | B25: Earthing of transmission towers: | C25: Lakhs/Lot | F25: =SUM(F99) -> 0.84 | G25: =F25*Input!$E$167 -> 0.1512 | H25: =F25+G25 -> 0.9912 | J25: =F25*BOQ_G!$AA$2 -> 0.714 | K25: =F25*BOQ_G!$AB$2 -> 0.1008 | L25: =SUM(J25:K25) -> 0.8148
A26: 5 | B26: ROW / Crop & Land Compensation | C26: Lakhs/Lot | F26: =SUM(F101:F104) -> 106.8 | G26: =F26*Input!$E$167 -> 19.224 | H26: =F26+G26 -> 126.024 | J26: =F26*BOQ_G!$AA$2 -> 90.78 | K26: =F26*BOQ_G!$AB$2 -> 12.816 | L26: =SUM(J26:K26) -> 103.596
A27: 6 | B27: Centage charges | C27: Lakhs/Lot | F27: =F106 -> 33.290493 | G27: =F27*Input!$E$167 -> 5.9922887 | H27: =F27+G27 -> 39.282781 | J27: =F27*BOQ_G!$AA$2 -> 28.296919 | K27: =F27*BOQ_G!$AB$2 -> 3.9948591 | L27: =SUM(J27:K27) -> 32.291778
A28: 7 | B28: Erection Charges | C28: Lakhs/Lot | F28: =F107+F108 -> 130.097 | G28: =F28*Input!$E$167 -> 23.41746 | H28: =F28+G28 -> 153.51446 | J28: =F28*BOQ_G!$AA$2 -> 110.58245 | K28: =F28*BOQ_G!$AB$2 -> 15.61164 | L28: =SUM(J28:K28) -> 126.19409
A29: B | B29: Transmission Line System | D29: 1 | E29: =IF(Input!$E$8="Yes",F29/D29,"") -> 1130.8432 | F29: =IF(Input!$E$8="Yes",SUM(F16:F28),"") -> 1130.8432 | G29: =IF(Input!$E$8="Yes",SUM(G16:G28),"") -> 203.55177 | H29: =IF(Input!$E$8="Yes",SUM(H16:H28),"") -> 1334.3949 | J29: =SUM(J16:J28) -> 961.21668 | K29: =SUM(K16:K28) -> 135.70118 | L29: =SUM(J29:K29) -> 1096.9179
B30: Augmentation Work @ BkTPS Substation
A31: 1 | B31: 220 kV Line Bay+ Bus Section Bay | C31: Lakhs/Lot | D31: =Input!D161 -> 2 | E31: =SUM(F190,F192,F194,F196,F198)/$D31 -> 42.778 | F31: =D31*E31 -> 85.556 | G31: =F31*Input!$F$167 -> 15.40008 | H31: =F31+G31 -> 100.95608 | J31: =F31*BOQ_G!$AA$2 -> 72.7226 | K31: =F31*BOQ_G!$AB$2 -> 10.26672 | L31: =SUM(J31:K31) -> 82.98932 | P31: =D31*E31 -> 85.556
A32: 2 | B32: EHV Cabling | C32: Lakhs/Mtr | D32: =Input!D162 -> 300 | E32: =(F200+F201+F202+F203)/D32 -> 0.64764 | F32: =D32*E32 -> 194.292 | G32: =F32*Input!$F$167 -> 34.97256 | H32: =F32+G32 -> 229.26456 | J32: =F32*BOQ_G!$AA$2 -> 165.1482 | K32: =F32*BOQ_G!$AB$2 -> 23.31504 | L32: =SUM(J32:K32) -> 188.46324 | P32: =D32*E32 -> 194.292
A33: 3 | B33: Miscellaneous (Control and Protection) | C33: Lakhs/No. | D33: =Input!D163 -> 1 | E33: =F12/SUM(D9:D11)*D31+F205 -> 142.2195 | F33: =D33*E33 -> 142.2195 | G33: =F33*Input!$F$167 -> 25.59951 | H33: =F33+G33 -> 167.81901 | J33: =F33*BOQ_G!$AA$2 -> 120.88657 | K33: =F33*BOQ_G!$AB$2 -> 17.06634 | L33: =SUM(J33:K33) -> 137.95291 | P33: =D33*E33 -> 142.2195
A34: C | B34: Augmentation Works | C34: Lot | D34: 1 | E34: =IF(Input!$E$8="Yes",F34/D34,"") -> 422.0675 | F34: =IF(Input!$E$8="Yes",SUM(F31:F33),"") -> 422.0675 | G34: =IF(Input!$E$8="Yes",SUM(G31:G33),"") -> 75.97215 | H34: =IF(Input!$E$8="Yes",SUM(H31:H33),"") -> 498.03965 | J34: =SUM(J31:J33) -> 358.75737 | K34: =SUM(K31:K33) -> 50.6481 | L34: =SUM(J34:K34) -> 409.40547
B35: Other Costs
B36: Contingency
A37: 1 | B37: =B3 -> Pooling Sub-Station - 300 MW, 33/220 KV | D37: =H13 -> 9078.6049 | E37: =BOQ_G!$D$220 -> 0.03 | F37: =IF(Input!$E$8="Yes",E37*D37,"") -> 272.35815 | G37: =IF(Input!$E$8="Yes",F37*Input!$F$167,"") -> 49.024467 | H37: =IF(Input!$E$8="Yes",F37+G37,"") -> 321.38261 | J37: =F37*0.85 -> 231.50443 | K37: =F37*0.15 -> 40.853722 | L37: =SUM(J37:K37) -> 272.35815
A38: 2 | B38: =B14 -> Transmission Line | D38: =H29 -> 1334.3949 | E38: =BOQ_G!$D$220 -> 0.03 | F38: =IF(Input!$E$8="Yes",E38*D38,"") -> 40.031848 | G38: =IF(Input!$E$8="Yes",F38*Input!$F$167,"") -> 7.2057326 | H38: =IF(Input!$E$8="Yes",F38+G38,"") -> 47.23758 | J38: =F38*0.85 -> 34.027071 | K38: =F38*0.15 -> 6.0047772 | L38: =SUM(J38:K38) -> 40.031848
A39: 3 | B39: =B30 -> Augmentation Work @ BkTPS Substation | D39: =H34 -> 498.03965 | E39: =BOQ_G!$D$220 -> 0.03 | F39: =IF(Input!$E$8="Yes",E39*D39,"") -> 14.941189 | G39: =IF(Input!$E$8="Yes",F39*Input!$F$167,"") -> 2.6894141 | H39: =IF(Input!$E$8="Yes",F39+G39,"") -> 17.630604 | J39: =F39*0.85 -> 12.700011 | K39: =F39*0.15 -> 2.2411784 | L39: =SUM(J39:K39) -> 14.941189
A40: D | B40: Contingency | D40: 1 | E40: =F40/D40 -> 327.33119 | F40: =SUM(F37:F39) -> 327.33119 | G40: =SUM(G37:G39) -> 58.919613 | H40: =SUM(H37:H39) -> 386.2508 | J40: =SUM(J37:J39) -> 278.23151 | K40: =SUM(K37:K39) -> 49.099678 | L40: =SUM(J40:K40) -> 327.33119
...

Sheet BOQ_I
A1: Transmission Line and Sub-station
A2: Summary | B2: Particulars | D2: Unit Rate | E2: Quantity | F2: Base Cost | G2: Tax | H2: Lumpsum Cost | J2: Equipment Cost | K2: Installation Cost
A3: A | B3: Land & Site Development | F3: =F15+F19 -> 1502.05 | G3: =G15+G19 -> 270.369 | H3: =F3+G3 -> 1772.419 | J3: =F3*BOQ_G!$AA$2 -> 1276.7425 | K3: =F3*BOQ_G!$AB$2 -> 180.246
A4: B | B4: Road Infrastructure | F4: =F22 -> 73.5 | G4: =G22 -> 13.23 | H4: =F4+G4 -> 86.73 | J4: =F4*BOQ_G!$AA$2 -> 62.475 | K4: =F4*BOQ_G!$AB$2 -> 8.82
B5: Infrastructure Cost Total | F5: =SUM(F3:F4) -> 1575.55 | G5: =SUM(G3:G4) -> 283.599 | H5: =SUM(H3:H4) -> 1859.149 | J5: =F5*BOQ_G!$AA$2 -> 1339.2175 | K5: =F5*BOQ_G!$AB$2 -> 189.066
A6: C | B6: Other Charges | F6: =F29 -> 208.24 | G6: =G29 -> 37.4832 | H6: =H29 -> 245.7232 | J6: =F6*BOQ_G!$AA$2 -> 177.004 | K6: =F6*BOQ_G!$AB$2 -> 24.9888
B7: Grand Total | F7: =F5+F6 -> 1783.79 | G7: =G5+G6 -> 321.0822 | H7: =H5+H6 -> 2104.8722 | J7: =F7*BOQ_G!$AA$2 -> 1516.2215 | K7: =F7*BOQ_G!$AB$2 -> 214.0548
B9: Infrastructure Development | C9: Unit Price | D9: Rate | E9: Quantity | F9: Base Cost | G9: Tax | H9: Total Cost
A10: A | B10: Land
A11: 1 | B11: Pooling S/S + Control Room | C11: Rs Lakh/ acre | D11: =(Input!D77*Input!E77+Input!D78*Input!E78)/SUM(Input!E77:E78) -> 0 | E11: =SUM(Input!E77:E78) -> 11.125 | F11: =D11*E11 -> 0 | G11: =F11*$J11 -> 0 | H11: =F11+G11 -> 0 | J11: 0.18
A12: 2 | B12: Approach Roads | C12: Rs Lakh/ acre | D12: =Input!D79 -> 0 | E12: =Input!E79 -> 0.6125 | F12: =D12*E12 -> 0 | G12: =F12*$J12 -> 0 | H12: =F12+G12 -> 0 | J12: 0.18
A13: 3 | B13: FSPV Master Control Room | C13: Rs Lakh/ acre | D13: =Input!D80 -> 0 | E13: =Input!E80 -> 3.8955 | F13: =D13*E13 -> 0 | G13: =F13*$J13 -> 0 | H13: =F13+G13 -> 0
A14: 4 | B14: Storage | C14: Rs Lakh/ acre | D14: =Input!D81 -> 0 | E14: =Input!E81 -> 4.125 | F14: =D14*E14 -> 0 | G14: =F14*$J14 -> 0 | H14: =F14+G14 -> 0 | J14: 0.18
B15: Land Total | C15: Rs Lakh | E15: =SUM(E11:E14) -> 19.758 | F15: =SUM(F11:F14) -> 0 | G15: =SUM(G11:G14) -> 0 | H15: =SUM(H11:H14) -> 0
A16: B | B16: Site Development
A17: 1 | B17: Site Development | C17: Rs Lakh | D17: =Input!D84 -> 100 | E17: =Input!E84 -> 15.0205 | F17: =D17*E17 -> 1502.05 | G17: =F17*$J17 -> 270.369 | H17: =F17+G17 -> 1772.419 | J17: =Input!$E$225 -> 0.18
A18: 2 | B18: Green Belt | C18: Rs Lakh | D18: =Input!D101 -> 0 | E18: =Input!E101 -> 0 | F18: =D18*E18 -> 0 | G18: =F18*$J18 -> 0 | H18: =F18+G18 -> 0 | J18: =Input!$E$225 -> 0.18
B19: Site Development Total | F19: =SUM(F17:F18) -> 1502.05 | G19: =SUM(G17:G18) -> 270.369 | H19: =SUM(H17:H18) -> 1772.419
A20: C | B20: Road Infrastructure
A21: 1 | B21: Access Road to Site | C21: Rs Lakh | D21: =Input!D86 -> 120 | E21: =Input!E86 -> 0.6125 | F21: =D21*E21 -> 73.5 | G21: =F21*$J21 -> 13.23 | H21: =F21+G21 -> 86.73 | J21: =Input!$E$225 -> 0.18
B22: Road Infrastructure Total | E22: =SUM(E21:E21) -> 0.6125 | F22: =SUM(F21:F21) -> 73.5 | G22: =SUM(G21:G21) -> 13.23 | H22: =SUM(H21:H21) -> 86.73
B24: Other Charges/Statutory Charges
A25: 1 | B25: Local Area Development Charges | C25: Rs Lakh | D25: =Input!D107 -> 100000 | E25: =Input!E107 -> 203.24 | F25: =D25*E25/10^5 -> 203.24 | G25: =F25*$J25 -> 36.5832 | H25: =F25+G25 -> 239.8232 | J25: =Input!$E$225 -> 0.18
A26: 2 | B26: Registration Cost | C26: Rs Lakh | D26: =Input!D108 -> 0 | E26: =Input!E108 -> 203.24 | F26: =D26*E26/10^5 -> 0 | G26: =F26*$J26 -> 0 | H26: =F26+G26 -> 0 | J26: =Input!$E$225 -> 0.18
A27: 3 | B27: Legal Charges | C27: Rs Lakh | D27: =Input!D109 -> 0 | E27: =Input!E109 -> 203.24 | F27: =D27*E27/10^5 -> 0 | G27: =F27*$J27 -> 0 | H27: =F27+G27 -> 0 | J27: =Input!$E$225 -> 0.18
A28: 4 | B28: Regulatory Charges | C28: Rs Lakh | D28: =Input!D110 -> 500000 | E28: =Input!E110 -> 1 | F28: =D28*E28/10^5 -> 5 | G28: =F28*$J28 -> 0.9 | H28: =F28+G28 -> 5.9 | J28: =Input!$E$225 -> 0.18
B29: Other Charges - Total | C29: Rs Lakh | F29: =SUM(F25:F28) -> 208.24 | G29: =SUM(G25:G28) -> 37.4832 | H29: =SUM(H25:H28) -> 245.7232

Sheet Working
B1: Particulars | C1: Units | D1: Inputs | E1: =YEAR(E2) -> 2026 | F1: =E1+1 -> 2027 | G1: =F1+1 -> 2028 | H1: =G1+1 -> 2029 | I1: =H1+1 -> 2030 | J1: =I1+1 -> 2031 | K1: =J1+1 -> 2032 | L1: =K1+1 -> 2033 | M1: =L1+1 -> 2034 | ... AJ1: =AI1+1 -> 2057
D2: =Input!D238 -> 45747 | E2: =EOMONTH(D2,12) -> 46112 | F2: =EOMONTH(E2,12) -> 46477 | G2: =EOMONTH(F2,12) -> 46843 | H2: =EOMONTH(G2,12) -> 47208 | I2: =EOMONTH(H2,12) -> 47573 | J2: =EOMONTH(I2,12) -> 47938 | K2: =EOMONTH(J2,12) -> 48304 | L2: =EOMONTH(K2,12) -> 48669 | ... AJ2: =EOMONTH(AI2,12) -> 57435
B3: Total Year Counter | D3: 0 | E3: =D3+1 -> 1 | F3: =E3+1 -> 2 | G3: =F3+1 -> 3 | H3: =G3+1 -> 4 | I3: =H3+1 -> 5 | J3: =I3+1 -> 6 | K3: =J3+1 -> 7 | L3: =K3+1 -> 8 | ... AJ3: =AI3+1 -> 32
B4: Is Operational ? | C4: =SUM(E4:AI4) -> 26 | E4: =IF(AND(E2>=Input!$E$180,E2<=Input!$E$182),1,0) -> 0 | F4: =IF(AND(F2>=Input!$E$180,F2<=Input!$E$182),1,0) -> 1 | G4: =IF(AND(G2>=Input!$E$180,G2<=Input!$E$182),1,0) -> 1 | H4: =IF(AND(H2>=Input!$E$180,H2<=Input!$E$182),1,0) -> 1 | I4: =IF(AND(I2>=Input!$E$180,I2<=Input!$E$182),1,0) -> 1 | J4: =IF(AND(J2>=Input!$E$180,J2<=Input!$E$182),1,0) -> 1 | K4: =IF(AND(K2>=Input!$E$180,K2<=Input!$E$182),1,0) -> 1 | L4: =IF(AND(L2>=Input!$E$180,L2<=Input!$E$182),1,0) -> 1 | ... AJ4: =IF(AND(AJ2>=Input!$E$180,AJ2<=Input!$E$182),1,0) -> 0
B5: Operational Year Number | E5: =SUM($E4:E$4) -> 0 | F5: =SUM($E4:F$4) -> 1 | G5: =SUM($E4:G$4) -> 2 | H5: =SUM($E4:H$4) -> 3 | I5: =SUM($E4:I$4) -> 4 | J5: =SUM($E4:J$4) -> 5 | K5: =SUM($E4:K$4) -> 6 | L5: =SUM($E4:L$4) -> 7 | ... AJ5: =SUM($E4:AJ$4) -> 26
B6: Days in year | E6: =E2-D2 -> 365 | F6: =F2-E2 -> 365 | G6: =G2-F2 -> 366 | H6: =H2-G2 -> 365 | I6: =I2-H2 -> 365 | J6: =J2-I2 -> 365 | K6: =K2-J2 -> 366 | L6: =L2-K2 -> 365 | ... AJ6: =AJ2-AI2 -> 365
B7: Days of Construction | E7: =E6-E8 -> 365 | F7: =F6-F8 -> 183 | G7: =G6-G8 -> 0 | H7: =H6-H8 -> 0 | I7: =I6-I8 -> 0 | J7: =J6-J8 -> 0 | K7: =K6-K8 -> 0 | L7: =L6-L8 -> 0
B8: Days in Operations | E8: =IF(E2=Input!$E$182,Input!$E$181-D2,IF(E2-Input!$E$178+1>=365,E2-D2,E2-Input!$E$178+1))*E4 -> 0 | F8: =IF(F2=Input!$E$182,Input!$E$181-E2,IF(F2-Input!$E$178+1>=365,F2-E2,F2-Input!$E$178+1))*F4 -> 182 | G8: =IF(G2=Input!$E$182,Input!$E$181-F2,IF(G2-Input!$E$178+1>=365,G2-F2,G2-Input!$E$178+1))*G4 -> 366 | H8: =IF(H2=Input!$E$182,Input!$E$181-G2,IF(H2-Input!$E$178+1>=365,H2-G2,H2-Input!$E$178+1))*H4 -> 365 | I8: =IF(I2=Input!$E$182,Input!$E$181-H2,IF(I2-Input!$E$178+1>=365,I2-H2,I2-Input!$E$178+1))*I4 -> 365 | J8: =IF(J2=Input!$E$182,Input!$E$181-I2,IF(J2-Input!$E$178+1>=365,J2-I2,J2-Input!$E$178+1))*J4 -> 365 | K8: =IF(K2=Input!$E$182,Input!$E$181-J2,IF(K2-Input!$E$178+1>=365,K2-J2,K2-Input!$E$178+1))*K4 -> 366 | L8: =IF(L2=Input!$E$182,Input!$E$181-K2,IF(L2-Input!$E$178+1>=365,L2-K2,L2-Input!$E$178+1))*L4 -> 365 | ... AJ8: =IF(AJ2=Input!$E$182,Input!$E$181-AI2,IF(AJ2-Input!$E$178+1>=365,AJ2-AI2,AJ2-Input!$E$178+1))*AJ4 -> 0
B9: Proportion of year in operation | E9: =IF(E6,E8/E6,0) -> 0 | F9: =IF(F6,F8/F6,0) -> 0.49863014 | G9: =IF(G6,G8/G6,0) -> 1 | H9: =IF(H6,H8/H6,0) -> 1 | I9: =IF(I6,I8/I6,0) -> 1 | J9: =IF(J6,J8/J6,0) -> 1 | K9: =IF(K6,K8/K6,0) -> 1 | L9: =IF(L6,L8/L6,0) -> 1 | ... AJ9: =IF(AJ6,AJ8/AJ6,0) -> 0
B10: Cumulative number of year in operation | E10: =D10+E9 -> 0 | F10: =E10+F9 -> 0.49863014 | G10: =F10+G9 -> 1.4986301 | H10: =G10+H9 -> 2.4986301 | I10: =H10+I9 -> 3.4986301 | J10: =I10+J9 -> 4.4986301 | K10: =J10+K9 -> 5.4986301 | L10: =K10+L9 -> 6.4986301 | ... AJ10: =AI10+AJ9 -> 24.99863
A12: CapEX
B13: Capacity of the Project | C13: MW | D13: =Input!E6 -> 203.24 | F13: MWp | G13: =Input!$E$4 -> 243.888
B14: Generation Project | C14: Unit | D14: Unit Cost | E14: Quantity | F14: Cost (Rs Lakh) | G14: Tax | H14: Total Cost
A15: II | B15: Capital Expenditure - Generation
A16: A | B16: SPV Modules | C16: Lot | D16: =BOQ_G!D2 -> 159 | E16: =BOQ_G!E2 -> 243.888 | F16: =BOQ_G!F2 -> 38728.483 | G16: =BOQ_G!G2 -> 5344.5306 | H16: =BOQ_G!H2 -> 44073.013
A17: B | B17: Inverters | C17: Lot | D17: =BOQ_G!D3 -> 13 | E17: =BOQ_G!E3 -> 203.24 | F17: =BOQ_G!F3 -> 2650.5 | G17: =BOQ_G!G3 -> 365.769 | H17: =BOQ_G!H3 -> 3016.269
A18: C | B18: Floating Structure for Module and inverters | C18: Lot | D18: =BOQ_G!D4 -> 135 | E18: =BOQ_G!E4 -> 243.888 | F18: =BOQ_G!F4 -> 32929.861 | G18: =BOQ_G!G4 -> 4544.3208 | H18: =BOQ_G!H4 -> 37474.182
A19: D | B19: Balance of Plant (Cables, SCB, Accessories) | C19: Lot | D19: =BOQ_G!D8 -> 40 | E19: =BOQ_G!E8 -> 243.888 | F19: =BOQ_G!F8 -> 9694.1833 | G19: =BOQ_G!G8 -> 1337.7973 | H19: =BOQ_G!H8 -> 11031.981
A20: E | B20: Civil Structure | C20: Lot | D20: =BOQ_G!D14 -> 7 | E20: =BOQ_G!E14 -> 243.888 | F20: =BOQ_G!F14 -> 1663.1343 | G20: =BOQ_G!G14 -> 229.51254 | H20: =BOQ_G!H14 -> 1892.6469
B21: Capital Expenditure - Generation | C21: Lot | F21: =SUM(F16:F20) -> 85666.161 | G21: =SUM(G16:G20) -> 11821.93 | H21: =SUM(H16:H20) -> 97488.091
A22: III | B22: Capital Expenditure - Transmission Evacuation
A23: A | B23: Pooling Sub-station | C23: MVA | D23: =F23/E23 -> 24.042916 | E23: =BOQ_T!D13 -> 320 | F23: =BOQ_T!F13 -> 7693.733 | G23: =BOQ_T!G13 -> 1384.8719 | H23: =BOQ_T!H13 -> 9078.6049
A24: B | B24: Transmission Line System | C24: kM | D24: =F24/E24 -> 282.71079 | E24: =Input!D118 -> 4 | F24: =BOQ_T!F29 -> 1130.8432 | G24: =BOQ_T!G29 -> 203.55177 | H24: =BOQ_T!H29 -> 1334.3949
A25: C | B25: Augmentation Works | C25: Lot | D25: =F25/E25 -> 422.0675 | E25: 1 | F25: =BOQ_T!F34 -> 422.0675 | G25: =BOQ_T!G34 -> 75.97215 | H25: =BOQ_T!H34 -> 498.03965
B26: Capital Expenditure - Transmission Evacuation | C26: Lot | F26: =SUM(F23:F25) -> 9246.6437 | G26: =SUM(G23:G25) -> 1664.3959 | H26: =SUM(H23:H25) -> 10911.04
A27: I | B27: Capital Expenditure - Infrastructure
A28: A | B28: Land & Site Development | C28: Lot | D28: =BOQ_I!D3 -> 0 | E28: =BOQ_I!E3 -> 0 | F28: =BOQ_I!F3 -> 1502.05 | G28: =BOQ_I!G3 -> 270.369 | H28: =SUM(F28:G28) -> 1772.419
A29: B | B29: Road Infrastructure | C29: Lot | D29: =BOQ_I!D4 -> 0 | E29: =BOQ_I!E4 -> 0 | F29: =BOQ_I!F4 -> 73.5 | G29: =BOQ_I!G4 -> 13.23 | H29: =SUM(F29:G29) -> 86.73
B30: Capital Expenditure - Infrastructure | C30: Lot | F30: =SUM(F28:F29) -> 1575.55 | G30: =SUM(G28:G29) -> 283.599 | H30: =SUM(H28:H29) -> 1859.149
A31: IV | B31: Capital Expenditure - Other Costs
A32: A | B32: Generation (Contingency, Insurance, Warranty, etc) | C32: Lot | F32: =BOQ_G!F19+BOQ_G!F21 -> 9449.5874 | G32: =BOQ_G!G19+BOQ_G!G21 -> 1304.0431 | H32: =BOQ_G!H19+BOQ_G!H21 -> 10753.63
A33: B | B33: Transmission (Contingency, Insurance, Warranty, etc) | C33: Lot | F33: =BOQ_T!F40 -> 327.33119 | G33: =BOQ_T!G40 -> 58.919613 | H33: =BOQ_T!H40 -> 386.2508
A34: C | B34: Other Charges/Statutory Charges | C34: Lot | F34: =BOQ_I!F6 -> 208.24 | G34: =BOQ_I!G6 -> 37.4832 | H34: =BOQ_I!H6 -> 245.7232
B35: Capital Expenditure - Other Costs | C35: Lot | F35: =SUM(F32:F34) -> 9985.1586 | G35: =SUM(G32:G34) -> 1400.4459 | H35: =SUM(H32:H34) -> 11385.604
B36: Total Project Cost w/o IDC | F36: =F21+F26+F30+F35 -> 106473.51 | G36: =G21+G26+G30+G35 -> 15170.371 | H36: =H21+H26+H30+H35 -> 121643.88
B37: Interest During Construction | C37: Lot | H37: =D52*100 -> 2612.319
B38: Grand Total | C38: Lot | F38: =F36+F37 -> 106473.51 | G38: =G36+G37 -> 15170.371 | H38: =H36+H37 -> 124256.2
B39: Capital Cost without IDC
A40: 1 | B40: Capital Expenditure - Generation & Transmission | C40: Rs Cr | F40: =(F26+F21)/100 -> 949.12805 | G40: =(G26+G21)/100 -> 134.86326 | H40: =(H26+H21)/100 -> 1083.9913
A41: 2 | B41: Capital Expenditure - Infrastructure | C41: Rs Cr | F41: =F30/100 -> 15.7555 | G41: =G30/100 -> 2.83599 | H41: =H30/100 -> 18.59149
...

Sheet Output
B2: Project Assumptions | C2: Units | D2: FSP | G2: Units | H2: FSP | K2: Capex Breakup | L2: Rs per Wp | M2: Rs Lakh /MW | N2: Rs Crore
B3: Project Assumptions | F3: Capital Expenditure | K3: Float Devices
B4: Capacity | C4: MWp | D4: =Input!$E$4 -> 243.888 | F4: Capex | G4: Rs Lakh | H4: =Working!D51*100 -> 121643.88 | I4: =H4/$D$4/100 -> 4.9876945 | J4: =H4/$D$5/100 -> 5.9852334 | K4: Floats and Platforms | L4: =ROUND(BOQ_G!H5/$D$4/10,3) -> 7.685 | M4: =ROUND(BOQ_G!H5/$D$5/1,2) -> 92.22 | N4: =M4*$D$5/100 -> 187.42793
B5: Capacity | C5: =Input!C6 -> MW | D5: =Input!E6 -> 203.24 | F5: IDC | G5: Rs Lakh | H5: =Working!D52*100 -> 2612.319 | I5: =H5/$D$4/100 -> 0.10711142 | J5: =H5/$D$5/100 -> 0.1285337 | K5: IT Platform | L5: =ROUND(BOQ_G!H6/$D$4/10,3) -> 2.802 | M5: =ROUND(BOQ_G!H6/$D$5/1,2) -> 33.63 | N5: =M5*$D$5/100 -> 68.349612
B6: CUF | C6: =Input!C7 -> % | D6: =Input!E7 -> 0.19317816 | F6: Capex including IDC | G6: Rs Lakh | H6: =SUM(H4:H5) -> 124256.2 | I6: =H6/$D$4/100 -> 5.0948059 | J6: =H6/$D$5/100 -> 6.1137671 | K6: Anchor and Mooring | L6: =ROUND(BOQ_G!H7/$D$4/10,3) -> 4.878 | M6: =ROUND(BOQ_G!H7/$D$5/1,2) -> 58.53 | N6: =M6*$D$5/100 -> 118.95637
B7: COD | C7: =Input!C178 -> Date | D7: =Input!E178 -> 46296 | K7: Float Devices | L7: =SUM(L4:L6) -> 15.365 | M7: =SUM(M4:M6) -> 184.38 | N7: =SUM(N4:N6) -> 374.73391
B8: Life of Project | C8: =Input!C179 -> Years | D8: =Input!E179 -> 25 | F8: Funding | K8: Solar PV System
B9: Funding Assumptions | F9: Commerical Loan 1 | G9: Rs Lakh | H9: =Working!D60*100 -> 86979.342 | K9: PV Module | L9: =ROUND(Working!$H$16/$D$4/10,2) -> 18.07 | M9: =ROUND(Working!$H$16/$D$5/1,2) -> 216.85 | N9: =M9*$D$5/100 -> 440.72594
B10: Commerical Loan 1 | C10: % | D10: =Input!E245 -> 0.7 | F10: Commerical Loan 2 | G10: Rs Lakh | H10: =Working!D61*100 -> 0 | K10: Inverter (including switchgear) | L10: =ROUND(Working!$H$17/$D$4/10,2) -> 1.24 | M10: =ROUND(Working!$H$17/$D$5/1,2) -> 14.84 | N10: =M10*$D$5/100 -> 30.160816
B11: Commerical Loan 2 | C11: % | D11: =Input!E246 -> 0 | F11: Grant/ Capital Subsidy | G11: Rs Lakh | H11: =Working!D62*100 -> 0 | K11: Balance of System (BoS) | L11: =ROUND((Working!$H$19)/$D$4/10,2) -> 4.52 | M11: =ROUND((Working!$H$19)/$D$5/1,2) -> 54.28 | N11: =M11*$D$5/100 -> 110.31867
B12: Grant/ Capital Subsidy | C12: % | D12: =Input!E247 -> 0 | F12: Equity | G12: Rs Lakh | H12: =Working!D63*100 -> 37276.861 | K12: Civil Structure | L12: =ROUND((Working!$H$20)/$D$4/10,2) -> 0.78 | M12: =ROUND((Working!$H$20)/$D$5/1,2) -> 9.31 | N12: =M12*$D$5/100 -> 18.921644
B13: Equity | C13: % | D13: =Input!E248 -> 0.3 | F13: Total Financing | G13: Rs Lakh | H13: =SUM(H9:H12) -> 124256.2 | K13: PV System | L13: =SUM(L9:L12) -> 24.61 | M13: =SUM(M9:M12) -> 295.28 | N13: =SUM(N9:N12) -> 600.12707
B14: Debt Assumptions | F14: Levelized Tariff | K14: Infrastructure
B15: =Input!B184 -> Moratorium Period (from start of operations) | C15: Years | D15: =Input!E184 -> 0 | F15: Generation O&M | G15: Rs/kWh | H15: =Working!D267 -> 0.62716264 | K15: Land and Site Development | L15: =ROUND(Working!$H$28/$D$4/10,2) -> 0.73 | M15: =ROUND(Working!$H$28/$D$5/1,2) -> 8.72 | N15: =M15*$D$5/100 -> 17.722528
B16: =Input!B185 -> Repayment Period | C16: Years | D16: =Input!E185 -> 15 | F16: Infrastructure O&M | G16: Rs/kWh | H16: =Working!D268 -> 0.11342013 | K16: Road Infrastructure | L16: =ROUND(Working!$H$29/$D$4/10,2) -> 0.04 | M16: =ROUND(Working!$H$29/$D$5/1,2) -> 0.43 | N16: =M16*$D$5/100 -> 0.873932
B17: =Input!B186 -> Interest Rate | C17: % | D17: =Input!E186 -> 0.06 | F17: Depreciation | G17: Rs/kWh | H17: =Working!D269 -> 1.6265289 | K17: Infrastructure | L17: =SUM(L15:L16) -> 0.77 | M17: =SUM(M15:M16) -> 9.15 | N17: =SUM(N15:N16) -> 18.59646
F18: Interest on Term Loan | G18: Rs/kWh | H18: =Working!D270 -> 0.74265307 | K18: Evacuation System
B19: Return Assumption | F19: Interest on WC | G19: Rs/kWh | H19: =Working!D271 -> 0.071544083 | K19: Sub-station | L19: =ROUND(Working!$H$23/$D$4/10,2) -> 3.72 | M19: =ROUND(Working!$H$23/$D$5/1,2) -> 44.67 | N19: =M19*$D$5/100 -> 90.787308
B20: =Input!B192 -> Return on Equity (RoE) - Post Tax | C20: % | D20: =Input!E192 -> 0.14 | F20: ROE | G20: Rs/kWh | H20: =Working!D274 -> 2.0722429 | K20: Transmission Line | L20: =ROUND(Working!$H$24/$D$4/10,2) -> 0.55 | M20: =ROUND(Working!$H$24/$D$5/1,2) -> 6.57 | N20: =M20*$D$5/100 -> 13.352868
F21: Project Tariff | G21: Rs/kWh | H21: =SUM(H15:H20) -> 5.2535517 | K21: Augmentation | L21: =ROUND(Working!$H$25/$D$4/10,2) -> 0.2 | M21: =ROUND(Working!$H$25/$D$5/1,2) -> 2.45 | N21: =M21*$D$5/100 -> 4.97938
B22: Working Capital Assumptions | K22: Evacuation System | L22: =SUM(L19:L21) -> 4.47 | M22: =SUM(M19:M21) -> 53.69 | N22: =SUM(N19:N21) -> 109.11956
B23: =Input!B216 -> Receivables | C23: Months | D23: =Input!E216 -> 1.5 | F23: Project Cost | G23: Rs Cr/MW | H23: =ROUND(H6/D5,2)*10^-2 -> 6.1138 | K23: Other Costs
B24: =Input!B217 -> O&M | C24: Months | D24: =Input!E217 -> 1 | F24: Project IRR | H24: =Working!D421 -> 0.087955957 | K24: Contingency, Insurance | L24: =ROUND(Working!$H$35/$D$4/10,2) -> 4.67 | M24: =ROUND(Working!$H$35/$D$5/1,2) -> 56.02 | N24: =M24*$D$5/100 -> 113.85505
B25: =Input!B218 -> Maintenance spares | C25: % | D25: =Input!E218 -> 0.15 | F25: Equity IRR | H25: =Working!D438 -> 0.134209 | K25: IDC | L25: =ROUND(Working!$D$52*100/$D$4/10,2) -> 1.07 | M25: =ROUND(Working!$D$52*100/$D$5/1,2) -> 12.85 | N25: =M25*$D$5/100 -> 26.11634
B26: =Input!B220 -> Interest on WC | C26: % | D26: =Input!E220 -> 0.115 | F26: EIRR | H26: =Working!D482 -> 0.19492022 | K26: Other Cost | L26: =SUM(L24:L25) -> 5.74 | M26: =SUM(M24:M25) -> 68.87 | N26: =SUM(N24:N25) -> 139.97139
F27: Discount Factor | H27: =Input!$E$228 -> 0.07476 | K27: Floating Solar Project Cost | L27: =L7+L13+L17+L22+L26 -> 50.955 | M27: =M7+M13+M17+M22+M26 -> 611.37 | N27: =N7+N13+N17+N22+N26 -> 1242.5484
F28: Average DSCR | H28: =Working!D405 -> 2.240914

Sheet Tables
G1: =BOQ_G!AA2 -> 0.85 | H1: =BOQ_G!AB2 -> 0.12 | I1: =BOQ_G!S37 -> 0.138
C2: Generation and Infrastructure BOQ | E2: =Input!J2 -> 5.2535517
B4: BOQ SPV
B5: S.N | C5: FPV plant | D5: Unit | E5: Quantity | F5: Unit Cost (Rs./Unit) | G5: Equipment Cost (Rs. Lakhs) | H5: Erection Cost (Rs. Lakhs) | I5: Base Cost (Rs. Lakhs) | J5: Tax (Rs. Lakhs) | K5: Total Cost (Rs. Lakhs) | AB5: Description | AC5: Total Cost (Rs Lakhs)
B6: A | C6: PV Modules | D6: Lot | E6: =BOQ_G!E36+BOQ_G!E37 -> 421385 | F6: =BOQ_G!D36 -> 9187.2 | G6: =I6*$G$1 -> 32906.46 | H6: =I6*$H$1 -> 4645.6179 | I6: =BOQ_G!F36+BOQ_G!F37 -> 38713.483 | J6: =I6*$I$1 -> 5342.4606 | K6: =I6+J6 -> 44055.943 | AB6: Land Cost | AC6: -
B7: B | C7: EL Testing | D7: Lot | E7: =BOQ_G!E38 -> 1 | F7: =BOQ_G!D38 -> 1000000 | G7: =I7*$G$1 -> 8.5 | H7: =I7*$H$1 -> 1.2 | I7: =BOQ_G!F38 -> 10 | J7: =I7*$I$1 -> 1.38 | K7: =I7+J7 -> 11.38 | AB7: PV Module Cost | AC7: =K9 -> 44073.013
B8: C | C8: Thermography | D8: Lot | E8: =BOQ_G!E39 -> 1 | F8: =BOQ_G!D39 -> 500000 | G8: =I8*$G$1 -> 4.25 | H8: =I8*$H$1 -> 0.6 | I8: =BOQ_G!F39 -> 5 | J8: =I8*$I$1 -> 0.69 | K8: =I8+J8 -> 5.69 | AB8: Inverter Cost | AC8: =K17 -> 3016.269
C9: Grand Total | G9: =I9*$G$1 -> 32919.21 | H9: =I9*$H$1 -> 4647.4179 | I9: =SUM(I6:I8) -> 38728.483 | J9: =SUM(J6:J8) -> 5344.5306 | K9: =SUM(K6:K8) -> 44073.013 | AB9: Floating Structure Cost | AC9: =K45 -> 37474.182
AB10: Electrical Infrastructure | AC10: =K82 -> 11031.383
AB11: Civil Infrastructure | AC11: =K92 -> 350.65686
AB12: Road & Drainage Infrastructure | AC12: =K124 -> 1859.149
B13: BOQ Inverter | AB13: Water Infrastructure | AC13: =K102 -> 318.64
B14: S.N | C14: FPV plant | D14: Unit | E14: Quantity | F14: Unit Cost (Rs./Unit) | G14: Equipment Cost (Rs. Lakhs) | H14: Erection Cost (Rs. Lakhs) | I14: Base Cost (Rs. Lakhs) | J14: Tax (Rs. Lakhs) | K14: Total Cost (Rs. Lakhs) | AB14: Street-Light
B15: A | C15: Inverter 4.4 MW | D15: Lot | E15: =BOQ_G!E41 -> 44 | F15: =BOQ_G!D41 -> 5700000 | G15: =I15*$G$1 -> 2131.8 | H15: =I15*$H$1 -> 300.96 | I15: =BOQ_G!F41 -> 2508 | J15: =I15*$I$1 -> 346.104 | K15: =I15+J15 -> 2854.104 | AB15: Cost of Power Evacuation
B16: B | C16: Inverter 1.1 MW | D16: Lot | E16: =BOQ_G!E42 -> 12 | F16: =BOQ_G!D42 -> 1187500 | G16: =I16*$G$1 -> 121.125 | H16: =I16*$H$1 -> 17.1 | I16: =BOQ_G!F42 -> 142.5 | J16: =I16*$I$1 -> 19.665 | K16: =I16+J16 -> 162.165 | AB16: Statutory and Other Fees
C17: Grand Total | G17: =I17*$G$1 -> 2252.925 | H17: =I17*$H$1 -> 318.06 | I17: =SUM(I15:I16) -> 2650.5 | J17: =SUM(J15:J16) -> 365.769 | K17: =SUM(K15:K16) -> 3016.269 | AB17: Project Cost
AB18: Interest During Construction (IDC)
AB19: Total project cost
B20: BOQ Floats
B21: S.N | C21: FPV plant | D21: Unit | E21: Quantity | F21: Unit Cost (Rs./Unit) | G21: Equipment Cost (Rs. Lakhs) | H21: Erection Cost (Rs. Lakhs) | I21: Base Cost (Rs. Lakhs) | J21: Tax (Rs. Lakhs) | K21: Total Cost (Rs. Lakhs)
B22: A | C22: Floating Structure
B23: 1 | C23: =BOQ_G!B45 -> OMF (Module Float) | D23: Rs. Per Float | E23: =BOQ_G!E45 -> 420544 | F23: =G23/E23*10^5 -> 888.25 | G23: =I23*$G$1 -> 3735.4821 | H23: =I23*$H$1 -> 527.36218 | I23: =BOQ_G!F45 -> 4394.6848 | J23: =I23*$I$1 -> 606.4665 | K23: =I23+J23 -> 5001.1513
B24: 2 | C24: =BOQ_G!B46 -> OMWF (Main Walkway Float) | D24: Rs. Per Float | E24: =BOQ_G!E46 -> 48032 | F24: =G24/E24*10^5 -> 3415.725 | G24: =I24*$G$1 -> 1640.641 | H24: =I24*$H$1 -> 231.61991 | I24: =BOQ_G!F46 -> 1930.1659 | J24: =I24*$I$1 -> 266.3629 | K24: =I24+J24 -> 2196.5288
B25: 3 | C25: =BOQ_G!B47 -> OLSF (Long Secondary Float) | D25: Rs. Per Float | E25: =BOQ_G!E47 -> 163308 | F25: =G25/E25*10^5 -> 2049.435 | G25: =I25*$G$1 -> 3346.8913 | H25: =I25*$H$1 -> 472.5023 | I25: =BOQ_G!F47 -> 3937.5192 | J25: =I25*$I$1 -> 543.37765 | K25: =I25+J25 -> 4480.8968
B26: 4 | C26: =BOQ_G!B48 -> OSSF (Small Secondary Float) | D26: Rs. Per Float | E26: =BOQ_G!E48 -> 148016 | F26: =G26/E26*10^5 -> 1366.29 | G26: =I26*$G$1 -> 2022.3278 | H26: =I26*$H$1 -> 285.5051 | I26: =BOQ_G!F48 -> 2379.2092 | J26: =I26*$I$1 -> 328.33087 | K26: =I26+J26 -> 2707.5401
