Workbook
Name _cp_table_9_566: Charges_Schedule!$A$3
Name Building_rate: '[1]A (1)'!$D$58
Name Building_rate_C: '[1]A (C)'!$D$58
Name Building_rate2: '[1]A (2)'!$D$58
Name Building_rate3: '[1]A (3)'!$D$58
Name Building_rate4: '[1]A (4)'!$D$58
Name Building_rate5: '[1]A (5)'!$D$58
Name contract_per_year2: '[1]A (2)'!$D$107
Name contract_per_year3: '[1]A (3)'!$D$107
Name contract_per_year4: '[1]A (4)'!$D$107
Name contract_per_year5: '[1]A (5)'!$D$107
Name contract_price: '[1]A (1)'!$D$108
Name contract_price_C: '[1]A (C)'!$D$108
Name contract_price2: '[1]A (2)'!$D$108
Name contract_price3: '[1]A (3)'!$D$108
Name contract_price4: '[1]A (4)'!$D$108
Name contract_price5: '[1]A (5)'!$D$108
Name contracts_per_year: '[1]A (1)'!$D$107
Name contracts_per_year_C: '[1]A (C)'!$D$107
Name converions_ratio5: '[1]A (5)'!$D$14
Name conversion_ratio: '[1]A (1)'!$D$14
Name conversion_ratio_C: '[1]A (C)'!$D$14
Name conversion_ratio2: '[1]A (2)'!$D$14
Name conversion_ratio3: '[1]A (3)'!$D$14
Name conversion_ratio4: '[1]A (4)'!$D$14
Name Cost_of_debt: '[1]A (1)'!$D$120
Name Cost_of_debt_C: '[1]A (C)'!$D$120
Name Cost_of_debt2: '[1]A (2)'!$D$120
Name Cost_of_debt3: '[1]A (3)'!$D$120
Name Cost_of_debt4: '[1]A (4)'!$D$120
Name Cost_of_debt5: '[1]A (5)'!$D$120
Name CPI: '[1]A (1)'!$D$83
Name CPI_2: '[1]A (2)'!$D$83
Name CPI_3: '[1]A (3)'!$D$83
Name CPI_4: '[1]A (4)'!$D$83
Name CPI_5: '[1]A (5)'!$D$83
Name CPI_C: '[1]A (C)'!$D$83
Name Creditor_days: '[1]A (1)'!$D$136
Name Creditor_days_C: '[1]A (C)'!$D$136
Name Creditor_days2: '[1]A (2)'!$D$136
Name Creditor_days3: '[1]A (3)'!$D$136
Name Creditor_days4: '[1]A (4)'!$D$136
Name Creditor_days5: '[1]A (5)'!$D$136
Name Debt_ratio: '[1]A (1)'!$D$117
Name Debt_ratio_C: '[1]A (C)'!$D$117
Name Debt_ratio2: '[1]A (2)'!$D$117
Name Debt_ratio3: '[1]A (3)'!$D$117
Name Debt_ratio4: '[1]A (4)'!$D$117
Name Debt_ratio5: '[1]A (5)'!$D$117
Name Debtor_days: '[1]A (1)'!$D$135
Name Debtor_days_C: '[1]A (C)'!$D$135
Name Debtor_days2: '[1]A (2)'!$D$135
Name Debtor_days3: '[1]A (3)'!$D$135
Name Debtor_days4: '[1]A (4)'!$D$135
Name Debtor_days5: '[1]A (5)'!$D$135
Name Electricity_tariff_eff: '[1]A (1)'!$D$95
Name Electricity_tariff_eff_C: '[1]A (C)'!$D$95
Name Electricity_tariff_eff2: '[1]A (2)'!$D$95
Name Electricity_tariff_eff3: '[1]A (3)'!$D$95
Name Electricity_tariff_eff4: '[1]A (4)'!$D$95

Sheet Compare
B1: Copy Paste | E1: Original-> | N1: Revised -> | O1: Developer | Y1: Revised -> | Z1: Loan
B2: =Inputs!H2 -> 3 | C2: =IF(Inputs!E66,"Developer","Loan") -> Developer | E2: Phase 1 | F2: 1 | H2: Phase 2 | I2: 2 | K2: Combined | L2: 3 | N2: Phase 1 | O2: 1 | Q2: Phase 2 | R2: 2 | T2: Combined | U2: 3 | W2: Check | Y2: Phase 1 | Z2: 1 | AB2: Phase 2 | AC2: 2 | AE2: Combined | AF2: 3 | AH2: Check
A3: Park Infrastructure Cost Breakup | E3: Rs Crore | F3: Rs Lakh per MW | H3: Rs Crore | I3: Rs Lakh per MW | K3: Rs Crore | L3: Rs Lakh per MW | N3: Rs Crore | O3: Rs Lakh per MW | Q3: Rs Crore | R3: Rs Lakh per MW | T3: Rs Crore | U3: Rs Lakh per MW | Y3: Rs Crore | Z3: Rs Lakh per MW | AB3: Rs Crore | AC3: Rs Lakh per MW | AE3: Rs Crore | AF3: Rs Lakh per MW
A4: Capital Expenditure
A5: Land | B5: =Dashboard!G5 -> 1.705258 | C5: =Dashboard!H5 -> 0.284 | E5: 0.817012 | F5: 0.272 | H5: 0.888246 | I5: 0.296 | K5: 1.705258 | L5: 0.284 | N5: 0.817012 | O5: 0.272 | Q5: 0.888246 | R5: 0.296 | T5: 1.705258 | U5: 0.284 | W5: =T5-Q5-N5 -> 0 | Y5: 0.817012 | Z5: 0.272 | AB5: 0.888246 | AC5: 0.296 | AE5: 1.705258 | AF5: 0.284 | AH5: =AE5-AB5-Y5 -> 0
A6: Road, Building & other civil | B6: =Dashboard!G6 -> 25.425 | C6: =Dashboard!H6 -> 4.238 | E6: 15.35 | F6: 5.117 | H6: 10.075 | I6: 3.358 | K6: 25.425 | L6: 4.238 | N6: 15.35 | O6: 5.117 | Q6: 10.075 | R6: 3.358 | T6: 25.425 | U6: 4.238 | W6: =T6-Q6-N6 -> 0 | Y6: 15.35 | Z6: 5.117 | AB6: 10.075 | AC6: 3.358 | AE6: 25.425 | AF6: 4.238 | AH6: =AE6-AB6-Y6 -> 0
A7: Evacuation - Sub-station | B7: =Dashboard!G7 -> 116.8 | C7: =Dashboard!H7 -> 19.467 | E7: 58.4 | F7: 19.467 | H7: 58.4 | I7: 19.467 | K7: 116.8 | L7: 19.467 | N7: 58.4 | O7: 19.467 | Q7: 58.4 | R7: 19.467 | T7: 116.8 | U7: 19.467 | W7: =T7-Q7-N7 -> 0 | Y7: 58.4 | Z7: 19.467 | AB7: 58.4 | AC7: 19.467 | AE7: 116.8 | AF7: 19.467 | AH7: =AE7-AB7-Y7 -> 0
A8: Evacuation - Transmission Line | B8: =Dashboard!G8 -> 104.31453 | C8: =Dashboard!H8 -> 17.386 | E8: 56.432711 | F8: 18.811 | H8: 47.881823 | I8: 15.961 | K8: 104.31453 | L8: 17.386 | N8: 56.432711 | O8: 18.811 | Q8: 47.881823 | R8: 15.961 | T8: 104.31453 | U8: 17.386 | W8: =T8-Q8-N8 -> 0 | Y8: 56.432711 | Z8: 18.811 | AB8: 47.881823 | AC8: 15.961 | AE8: 104.31453 | AF8: 17.386 | AH8: =AE8-AB8-Y8 -> 0
A9: Other Costs | B9: =Dashboard!G9 -> 63.066421 | C9: =Dashboard!H9 -> 10.511 | E9: 52.827545 | F9: 17.609 | H9: 51.624355 | I9: 17.208 | K9: 104.4519 | L9: 17.409 | N9: 31.50242 | O9: 10.501 | Q9: 31.565162 | R9: 10.522 | T9: 63.067582 | U9: 10.511 | W9: =T9-Q9-N9 -> -1.1209828e-08 | Y9: 31.50242 | Z9: 10.501 | AB9: 31.565162 | AC9: 10.522 | AE9: 63.067582 | AF9: 10.511 | AH9: =AE9-AB9-Y9 -> -1.1209828e-08
A10: Base Cost Total | B10: =Dashboard!G10 -> 311.31121 | C10: =Dashboard!H10 -> 51.89 | E10: 183.82727 | F10: 61.28 | H10: 168.86942 | I10: 56.29 | K10: 352.69669 | L10: 58.78 | N10: 162.50214 | O10: 54.17 | Q10: 148.81023 | R10: 49.6 | T10: 311.31237 | U10: 51.89 | W10: =T10-Q10-N10 -> -1.1209835e-08 | Y10: 162.50214 | Z10: 54.17 | AB10: 148.81023 | AC10: 49.6 | AE10: 311.31237 | AF10: 51.89 | AH10: =AE10-AB10-Y10 -> -1.1209835e-08
A11: Contingency & Insurance Charges | B11: =Dashboard!G11 -> 9.1237087 | C11: =Dashboard!H11 -> 1.521 | E11: 4.9307893 | F11: 1.644 | H11: 4.5395223 | I11: 1.513 | K11: 9.4703025 | L11: 1.578 | N11: 4.7574854 | O11: 1.586 | Q11: 4.3662671 | R11: 1.455 | T11: 9.1237435 | U11: 1.521 | W11: =T11-Q11-N11 -> -9.0403363e-06 | Y11: 4.7574854 | Z11: 1.586 | AB11: 4.3662671 | AC11: 1.455 | AE11: 9.1237435 | AF11: 1.521 | AH11: =AE11-AB11-Y11 -> -9.0403363e-06
A12: Capital Expenditure | B12: =Dashboard!G12 -> 320.43492 | C12: =Dashboard!H12 -> 53.411 | E12: 188.75806 | F12: 62.924 | H12: 173.40895 | I12: 57.803 | K12: 362.16699 | L12: 60.358 | N12: 167.25963 | O12: 55.756 | Q12: 153.1765 | R12: 51.055 | T12: 320.43612 | U12: 53.411 | W12: =T12-Q12-N12 -> -9.0515461e-06 | Y12: 167.25963 | Z12: 55.756 | AB12: 153.1765 | AC12: 51.055 | AE12: 320.43612 | AF12: 53.411 | AH12: =AE12-AB12-Y12 -> -9.0515461e-06
A13: IDC | B13: =Dashboard!G13 -> 9.2617535 | C13: =Dashboard!H13 -> 0.154 | E13: 5.596097 | F13: 0.187 | H13: 5.1413022 | I13: 0.171 | K13: 10.737399 | L13: 0.179 | N13: 5.3020063 | O13: 0.177 | Q13: 4.9063376 | R13: 0.164 | T13: 10.208344 | U13: 0.17 | W13: =T13-Q13-N13 -> -9.9326625e-08 | Y13: 5.3020063 | Z13: 0.177 | AB13: 4.9063376 | AC13: 0.164 | AE13: 10.208344 | AF13: 0.17 | AH13: =AE13-AB13-Y13 -> -9.9326625e-08
A14: Capex including IDC | B14: =Dashboard!G14 -> 329.69667 | C14: =Dashboard!H14 -> 53.565 | E14: 194.35415 | F14: 63.111 | H14: 178.55025 | I14: 57.974 | K14: 372.90439 | L14: 60.537 | N14: 172.56163 | O14: 55.933 | Q14: 158.08284 | R14: 51.219 | T14: 330.64446 | U14: 53.581 | W14: =T14-Q14-N14 -> -9.1508728e-06 | Y14: 172.56163 | Z14: 55.933 | AB14: 158.08284 | AC14: 51.219 | AE14: 330.64446 | AF14: 53.581 | AH14: =AE14-AB14-Y14 -> -9.1508728e-06
W15: =T15-Q15-N15 -> 0
A16: Financing | B16: =Dashboard!G16 -> Rs Crore | C16: =Dashboard!H16 -> 0 | E16: Rs Crore | H16: Rs Crore | K16: Rs Crore | N16: Rs Crore | O16: 0 | Q16: Rs Crore | R16: 0 | T16: Rs Crore | U16: 0 | Y16: Rs Crore | Z16: 0 | AB16: Rs Crore | AC16: 0 | AE16: Rs Crore | AF16: 0
A17: Commerical Loan 1 | B17: =Dashboard!G17 -> 161.55137 | C17: =Dashboard!H17 -> 0.49 | E17: 95.233536 | F17: 0.49 | H17: 87.489622 | I17: 0.49 | K17: 182.72315 | L17: 0.49 | N17: 84.555201 | O17: 0.49 | Q17: 77.46059 | R17: 0.49 | T17: 162.01579 | U17: 0.49 | W17: =T17-Q17-N17 -> -4.4839276e-06 | Y17: 84.555201 | Z17: 0.49 | AB17: 77.46059 | AC17: 0.49 | AE17: 162.01579 | AF17: 0.49 | AH17: =AE17-AB17-Y17 -> -4.4839276e-06
A18: Commerical Loan 2 | B18: =Dashboard!G18 -> 0 | C18: =Dashboard!H18 -> 0 | E18: 0 | F18: 0 | H18: 0 | I18: 0 | K18: 0 | L18: 0 | N18: 0 | O18: 0 | Q18: 0 | R18: 0 | T18: 0 | U18: 0 | W18: =T18-Q18-N18 -> 0 | Y18: 0 | Z18: 0 | AB18: 0 | AC18: 0 | AE18: 0 | AF18: 0 | AH18: =AE18-AB18-Y18 -> 0
A19: Grant/ Capital Subsidy | B19: =Dashboard!G19 -> 98.909002 | C19: =Dashboard!H19 -> 0.3 | E19: 58.306246 | F19: 0.3 | H19: 53.565074 | I19: 0.3 | K19: 111.87132 | L19: 0.3 | N19: 51.76849 | O19: 0.3 | Q19: 47.424851 | R19: 0.3 | T19: 99.193338 | U19: 0.3 | W19: =T19-Q19-N19 -> -2.7452618e-06 | Y19: 51.76849 | Z19: 0.3 | AB19: 47.424851 | AC19: 0.3 | AE19: 99.193338 | AF19: 0.3 | AH19: =AE19-AB19-Y19 -> -2.7452618e-06
A20: Deferred Capital Subisdy | B20: =Dashboard!G20 -> -15.807321 | C20: =Dashboard!H20 -> -0.047945041 | N20: -8.3673811 | O20: -0.048489232 | Q20: -7.5235497 | R20: -0.047592452 | T20: -15.890929 | U20: -0.048060474 | Y20: -8.3673811 | Z20: -0.048489232 | AB20: -7.5235497 | AC20: -0.047592452 | AE20: -15.890929 | AF20: -0.048060474
A21: Equity | B21: =Dashboard!G21 -> 0 | C21: =Dashboard!H21 -> 0 | E21: 0 | F21: 0 | H21: 0 | I21: 0 | K21: 0 | L21: 0 | N21: 0 | O21: 0 | Q21: 0 | R21: 0 | T21: 0 | U21: 0 | W21: =T21-Q21-N21 -> 0 | Y21: 0 | Z21: 0 | AB21: 0 | AC21: 0 | AE21: 0 | AF21: 0 | AH21: =AE21-AB21-Y21 -> 0
A22: Upfront Contribution from Developer | B22: =Dashboard!G22 -> 85.043622 | C22: =Dashboard!H22 -> 0.25794504 | E22: 40.814372 | F22: 0.21 | H22: 37.495552 | I22: 0.21 | K22: 78.309923 | L22: 0.21 | N22: 44.605324 | O22: 0.25848923 | Q22: 40.720945 | R22: 0.25759245 | T22: 85.326266 | U22: 0.25806047 | W22: =T22-Q22-N22 -> -3.2895817e-06 | Y22: 36.237943 | Z22: 0.21 | AB22: 33.197396 | AC22: 0.21 | AE22: 69.435337 | AF22: 0.21 | AH22: =AE22-AB22-Y22 -> -1.9216833e-06
A23: Total | B23: =Dashboard!G24 -> 329.69667 | C23: =Dashboard!H24 -> 1 | E23: 194.35415 | F23: 1 | H23: 178.55025 | I23: 1 | K23: 372.90439 | L23: 1 | N23: 172.56163 | O23: 1 | Q23: 158.08284 | R23: 1 | T23: 330.64446 | U23: 1 | W23: =T23-Q23-N23 -> -9.1508727e-06 | Y23: 172.56163 | Z23: 1 | AB23: 158.08284 | AC23: 1 | AE23: 330.64446 | AF23: 1 | AH23: =AE23-AB23-Y23 -> -9.1508727e-06
W24: =T24-Q24-N24 -> 0 | AH24: =AE24-AB24-Y24 -> 0
A25: Check Contribution | E25: =SUM(E27:E29)-E22 -> 0 | H25: =SUM(H27:H29)-H22 -> 0 | K25: =SUM(K27:K29)-K22 -> 0
A26: Upfront Charges (Rs Cr) | E26: Rs Cr | H26: Rs Cr | K26: Rs Cr
A27: Execution Date for ISA + 0.5 month | B27: =Dashboard!K5 -> 20.770891 | C27: =Dashboard!L5 -> 3.4618151 | E27: 10.623833 | F27: 3.5412775 | H27: 9.8500763 | I27: 3.2833588 | K27: 20.473908 | L27: 3.412318 | N27: 10.871383 | O27: 3.6237943 | Q27: 9.9592187 | R27: 3.3197396 | T27: 20.830601 | U27: 3.4717668 | W27: =T27-Q27-N27 -> -5.7650498e-07 | Y27: 10.871383 | Z27: 3.6237943 | AB27: 9.9592187 | AC27: 3.3197396 | AE27: 20.830601 | AF27: 3.4717668 | AH27: =AE27-AB27-Y27 -> -5.7650498e-07
A28: Execution Date for ISA + 6 month | B28: =Dashboard!K6 -> 24.232706 | C28: =Dashboard!L6 -> 4.0387843 | E28: 12.852587 | F28: 4.2841955 | H28: 11.62969 | I28: 3.8765633 | K28: 24.482276 | L28: 4.0803793 | N28: 12.68328 | O28: 4.22776 | Q28: 11.619088 | R28: 3.8730295 | T28: 24.302368 | U28: 4.0503946 | W28: =T28-Q28-N28 -> -6.7258915e-07 | Y28: 12.68328 | Z28: 4.22776 | AB28: 11.619088 | AC28: 3.8730295 | AE28: 24.302368 | AF28: 4.0503946 | AH28: =AE28-AB28-Y28 -> -6.7258915e-07
A29: Execution Date for ISA + 12 months | B29: =Dashboard!K7 -> 40.040026 | C29: =Dashboard!L7 -> 6.6733377 | E29: 17.337953 | F29: 5.7793178 | H29: 16.015786 | I29: 5.3385953 | K29: 33.353739 | L29: 5.5589564 | N29: 21.050661 | O29: 7.0168871 | Q29: 19.142638 | R29: 6.3808794 | T29: 40.193297 | U29: 6.6988829 | W29: =T29-Q29-N29 -> -2.0404876e-06 | Y29: 12.68328 | Z29: 4.22776 | AB29: 11.619088 | AC29: 3.8730295 | AE29: 24.302368 | AF29: 4.0503946 | AH29: =AE29-AB29-Y29 -> -6.7258915e-07
A30: Project CoD + 1 day | B30: =Dashboard!K10 -> 5.4491489 | C30: =Dashboard!L10 -> 0.90819149 | E30: 14.582124 | H30: 14.013315 | K30: 24.672852 | N30: 5.2515479 | O30: 1.750516 | Q30: 5.5785505 | R30: 1.8595168 | T30: 6.9058268 | U30: 1.1509711 | W30: =T30-Q30-N30 -> -3.9242717 | Y30: 14.053505 | Z30: 4.6845017 | AB30: 13.49285 | AC30: 4.4976167 | AE30: 23.622082 | AF30: 3.9370137 | AH30: =AE30-AB30-Y30 -> -3.9242731
A31: Project CoD + 0.5 years + 1 day | B31: =Dashboard!K11 -> 9.8409561 | C31: =Dashboard!L11 -> 1.6401593 | E31: 5.7492638 | H31: 5.5506342 | K31: 11.532482 | N31: 5.200448 | O31: 1.7334827 | Q31: 5.0287913 | R31: 1.6762638 | T31: 10.460274 | U31: 1.743379 | W31: =T31-Q31-N31 -> 0.23103458 | Y31: 5.1814293 | Z31: 1.7271431 | AB31: 5.0116907 | AC31: 1.6705636 | AE31: 10.424155 | AF31: 1.7373591 | AH31: =AE31-AB31-Y31 -> 0.23103459
A32: Project CoD + 1 years + 1 day | B32: =Dashboard!K12 -> 21.846455 | C32: =Dashboard!L12 -> 3.6410759 | N32: 11.582949 | O32: 3.860983 | Q32: 10.885335 | R32: 3.628445 | T32: 22.514267 | U32: 3.7523779 | W32: =T32-Q32-N32 -> 0.045983303 | Y32: 11.583963 | Z32: 3.861321 | AB32: 10.886247 | AC32: 3.6287489 | AE32: 22.516193 | AF32: 3.7526988 | AH32: =AE32-AB32-Y32 -> 0.045983303
A33: Total | B33: =Dashboard!K2 -> 663.87665 | N33: 342.7365 | Q33: 337.12871 | T33: 675.80194 | W33: =T33-Q33-N33 -> -4.0632675 | Y33: 343.15303 | AB33: 337.50323 | AE33: 676.59299 | AH33: =AE33-AB33-Y33 -> -4.0632675
A34: Revenue | B34: =Working!$D$413 -> 594.64035 | N34: 306.49856 | Q34: 303.93131 | T34: 606.3666 | W34: =T34-Q34-N34 -> -4.0632656 | Y34: 306.91509 | AB34: 304.30583 | AE34: 607.15765 | AH34: =AE34-AB34-Y34 -> -4.0632656
A35: Levelized Cost | B35: =Working!$D$451 -> 2.4589586 | N35: 2.6298805 | Q35: 2.5280595 | T35: 2.5449831 | Y35: 2.6388215 | AB35: 2.5360992 | AE35: 2.5534733
A36: Check - Contribution | B36: =SUM(B27:B29)-B22 -> 0 | N36: =SUM(N27:N29)-N22 -> 0 | Q36: =SUM(Q27:Q29)-Q22 -> 0 | T36: =SUM(T27:T29)-T22 -> 0 | W36: =SUM(W27:W29)-W22 -> 7.1054274e-15 | Y36: =SUM(Y27:Y29)-Y22 -> 0 | AB36: =SUM(AB27:AB29)-AB22 -> 0 | AE36: =SUM(AE27:AE29)-AE22 -> 0 | AH36: =SUM(AH27:AH29)-AH22 -> 1.7763568e-15
A37: First Installment | N37: =N30-Y30 -> -8.8019571 | Q37: =Q30-AB30 -> -7.9142997 | T37: =T30-AE30 -> -16.716255
N38: =N37-N20 -> -0.43457597 | Q38: =Q37-Q20 -> -0.39074997 | T38: =T37-T20 -> -0.82532587

Sheet Norms
B1: Norms for Capex | C1: MNRE Revised Norms | D1: Omkareshwar Model | F1: Actual Rs Cr | G1: Ceiling
A2: 1 | B2: Internal Evacuation incl bays, S/S, Transformers, T/L | C2: Schedule of STU/ CTU | D2: As per CTU; | F2: to be revised to STU cost schedule
A3: 2 | B3: Road, water infra, building fencing, street lighting | C3: As per Schedule of rates of PWD of GoMP | D3: As per PWD rates - RUMSL to confirm | F3: =Capex!I14+Capex!I19 -> 2542.5 | G3: =F3 -> 2542.5
A4: 3 | B4: Incidental Expenses during construction - Pre-operative costs, IDC, Finance Cost, Project Management Costs | C4: upto 10.75% of Capex | D4: =F4/(Capex!I61/100) -> 0.095194694 | F4: =Capex!I129+Capex!I60/100 -> 31.385374 | G4: =10.75%*Capex!I61/100 -> 35.442393
A5: 4 | B5: Contingency | C5: Upto 3% of Capex | D5: =ROUND(Capex!I56/Capex!I54,3) -> 0.028 | F5: =Capex!I56/100 -> 8.6385598 | G5: =3%*Capex!I54/100 -> 9.3393364
A6: 5 | B6: Grid Connectivity, LTOA charges, ESIA Charges | C6: As per rates notified by concerned agencies/ STU/ CTU | D6: As per CERC guidelines
A7: 6 | B7: Land Charges, Registration, Land conversion, Land Crop compensation, ROW | C7: As per rates notified by State Govt or its agencies | D7: State regulations
B9: Norms for O&M | C9: MNRE Revised Norms | D9: Omkareshwar Model | F9: Actual Rs Cr | G9: Ceiling
A10: 1 | B10: Internal Evacuation incl bays, S/S, Transformers, T/L | C10: As per Norms of CERC/ SERC | D10: =Inputs!E90 -> 1.047 | F10: =Working!J304 -> 3.0844558 | G10: =F10 -> 3.0844558
A11: 2 | B11: Road, water infra, building fencing, street lighting | C11: As per schedule of rates of PWD subject to ceiling of 5% of capex | D11: =F11/G11 -> 0.0064244393 | F11: =Inputs!E87 -> 0.1 | G11: =5%*Capex!I54/100 -> 15.565561
A12: 3 | B12: Establishment, admin, manpower | C12: As per schedule of rates of PWD sub to ceiling of 10% of O&M charges above (1&2) | D12: =F12/G12 -> 0.31396221 | F12: =Working!J303 -> 0.58554004 | G12: =10%*(G10+G11) -> 1.8650016
A13: 4 | B13: Power consumption charges, water consumption charges, land lease rentals | C13: As per rates finalized by state govt or its agencies | D13: Nil
A14: 5 | B14: Annual Escalation | C14: As per CERC/ SERC regulations | D14: =Inputs!F90 -> 0.037 | F14: =D14 -> 0.037 | G14: 0.037

Sheet Inputs
A1: RUMSL | C1: Units | E1: Input | G1: Bridge Financing | H1: =IF(E66,"Developer","Loan") -> Developer | I1: Circularity | J1: TRUE | Q1: Module size(Wp) | U1: 1 | V1: Yes
A2: Project | G2: Phase | H2: 3 | I2: 1=Phase 1; 2=Phase 2; 3=Combined | U2: 2 | V2: No
B3: Capacity of the Project | C3: MW | E3: =IF($H$2=1,300,IF($H$2=2,300,600)) -> 600 | G3: ESIA, IE, Legal,DPR, Consultancy | H3: 0.5 | I3: =IF(H3=0.5,"Shared","Independent") -> Shared | P3: Option 1 | Q3: 350 | T3: TRUE | U3: 3
B4: Conversion Factor | C4: AC:DC | E4: 1.4 | G4: Connectivity | H4: 0.5 | I4: =IF(H4=0.5,"Shared","Independent") -> Shared | P4: 2.5 | Q4: 44 | T4: FALSE
B5: CUF of the project | C5: % | E5: 0.2494 | G5: Regulatory | H5: 0.5 | I5: =IF(H5=0.5,"Shared","Independent") -> Shared | P5: Option 2 | Q5: 445
B6: Annual Generation | C6: MU | E6: =E5*E3*8.76 -> 1310.8464 | G6: Common Corridor | H6: Yes | I6: =IF(H6="Yes","Combined cost","Bifurcated Cost") -> Combined cost | P6: Plot Capacity (MW) | Q6: Mooring Lines (No)
B7: Derating | C7: % | E7: 0.0025
B8: Capital Cost of Solar Project | C8: Rs Cr/ MW | E8: 5.06 | G8: (Estimates)
B9: Levelized Generation Tariff | C9: Rs per Unit | E9: 2.95 | G9: (Estimates)
A10: Solar Park
B11: Stamp Duty | C11: Land | E11: =12.5%*0 -> 0 | F11: NA | G11: As per RUMSL inputs dated 26-Oct-2021
B12: Registration Charges - Land | C12: Land | E12: 0 | F12: NA | G12: As per RUMSL inputs dated 26-Oct-2021
B13: Admin charges - Land | C13: Land | E13: =1.5%*0+0 -> 0 | F13: NA | G13: As per RUMSL inputs dated 26-Oct-2021
A14: MPTransco | B14: PMC Cost - Transmission | C14: % | E14: 0.08 | F14: Yes | G14: As per RUMSL inputs dated 26-Oct-2021
B15: PMC charges to MPUVNL | E15: 0 | F15: Yes | G15: As per RUMSL inputs dated 26-Oct-2021 (Changed from 10% to 8%), 15-Mar-2022 (8% to 0%) - To be specified in ISA
B16: Upfront PMC charges to MPUVNL | E16: 1 | F16: Yes | G16: As per RUMSL inputs dated 08-Dec-2021
B17: Period for payment of remainder PMC charges (years) | E17: 1 | F17: Yes
B18: Local Area Development Charges | C18: Rs Lakh/ MW | E18: 1 | F18: Yes
B19: LAD - Years for Payment | C19: # | E19: 2 | F19: Yes | G19: =74.37+63.92+74.37+35.77 -> 248.43 | H19: =58.45+52.4+58.45+29.29 -> 198.59
B20: Registration Cost | C20: Rs Lakh/ MW | E20: 1 | F20: Yes
A21: Not Used | B21: PSF Fees | C21: Upfront | E21: 0.001 | G21: As per RUMSL inputs dated 26-Oct-2021
A22: Not Used | B22: PSF Fees - Applicable | E22: FALSE | F22: No | G22: As per RUMSL inputs dated 26-Oct-2021 - Annual Charges
B23: Financing Cost (first 100 Cr) | C23: % | E23: 0.0025 | F23: Yes | G23: As per RUMSL inputs dated 15-Mar-2022
B24: Financing Cost (beyond 100 Cr) | C24: % | E24: 0.0025 | F24: Yes | G24: As per RUMSL inputs dated 26-Oct-2021, 15-Mar-2022
B25: ESIA Cost | C25: Rs Lakh | E25: =69.3 -> 69.3 | F25: Yes | G25: As per RUMSL inputs dated 26-Oct-2021
B26: RAP/ LRP Cost | C26: Rs Lakh/ MW | E26: =1500/600 -> 2.5 | F26: Yes | G26: As per RUMSL inputs dated 08-Dec-2021/ 01-Mar-2022/ updated RUMSL mail 25-Mar-22 | L26: =E26*600/100 -> 15
B27: ESMP Cost | C27: Rs Lakh/ MW | E27: =ROUND(650/600,4) -> 1.0833 | F27: Yes | G27: As per RUMSL inputs dated 08-Dec-2021/ updated RUMSL mail 25-Mar-2022 | L27: =E27*600/100 -> 6.4998
B28: Independent Engineer Fee | C28: Rs Lakh/ visit | E28: 2 | F28: Yes | G28: As per RUMSL inputs dated 26-Oct-2021
B29: Legal Charges | C29: Rs Lakh | E29: 15 | F29: Yes | G29: As per RUMSL inputs dated 26-Oct-2021
B30: LTA Application Cost | C30: Rs Lakh | E30: 25 | F30: Yes | G30: Grant of connectivity, LTA application (As per the CERC's Grant of Connectivity regulations); As per RUMSL inputs dated 01-Mar-2022
B31: Regulatory Charges | C31: Rs Lakh | E31: =IF($H$2=1,5,IF($H$2=2,30,35)) -> 35 | F31: Yes | G31: As per RUMSL inputs dated 26-Oct-2021 (Tariff Adoption: 25 L; Deviation Petition:5 L)/ 01-Mar-2022
B32: DPR Preparation | C32: Rs Lakh | E32: =IF($H$2=1,0.5,IF($H$2=2,0.5,1))*111*1.18*600/(600+950) -> 50.701935 | F32: Yes | G32: As per RUMSL inputs dated 08-Dec-2021/ 01-Mar-2022
B33: TA Consultancy Charges | C33: Rs Lakh | E33: =IF($H$2=1,0.5,IF($H$2=2,0.5,1))*1.74*1.18*100 -> 205.32 | F33: Yes | G33: Actuals with taxes; As per RUMSL inputs dated 01-Mar-2022
A34: Financial Parameters
B35: Taxes | C35: % | E35: 0.18
B36: Contingency | C36: % | E36: 0.03 | G36: Max as per revised guidelines
A37: Solar Park Infrastructure Project Details | K37: As per SBG
F38: Site | G38: Sub-station | H38: Tr Lines | I38: Other | K38: Sub-station | L38: 21 | M38: Months
B39: Project Start Date | C39: Date | E39: 44713 | F39: =E39 -> 44713 | G39: =E39 -> 44713 | H39: =E39 -> 44713 | I39: =E39 -> 44713 | K39: Transmission Lines | L39: 21 | M39: Months
B40: Park Construction Period | C40: Month | E40: =MAX(F40:I40) -> 16 | F40: 6 | G40: 16 | H40: 16 | I40: 12 | K40: Other Infrastructure | L40: 21 | M40: Months
...

Sheet Dashboard
B1: Assumptions | F1: Results | J1: Comprehensive Park Charges | N1: Modified Comprehensive Park Charges | R1: Reduction | S1: (Deducted A&G charges) | U1: Year | V1: Cash
F2: Phasing | G2: =Inputs!H1 -> Developer | H2: =IF(Inputs!$H$2=1,"Phase 1",IF(Inputs!$H$2=2,"Phase 2","Combined")) -> Combined | K2: =SUM(K5:K60) -> 663.87665 | O2: =SUM(O5:O60) -> 607.29426 | R2: =SUM(R5:R60) -> 56.582387
C3: Units | F3: Park Infrastructure Cost Breakup | G3: Rs Crore | H3: Rs Lakh per MW | J3: Solar park charges as per milestone | K3: Solar Park-Infra | N3: Solar park charges as per milestone | O3: Solar Park-Infra
B4: General | F4: Capital Expenditure | I4: Target | J4: Upfront Charges (Rs Cr) | K4: Rs Cr | L4: Rs Lakhs/MW | N4: Upfront Charges (Rs Cr)
B5: Capacity | C5: =Inputs!C3 -> MW | D5: =Inputs!E3 -> 600 | F5: Land | G5: =(Capex!I6)/100 -> 1.705258 | H5: =ROUND(G5*100/$D$5,3) -> 0.284 | J5: Execution Date for ISA + 0.5 month | K5: =SUMIFS(Working!$E$81:$BL$81,Working!$E$2:$BL$2,S5)+SUMIFS(Working!$E$413:$BL$413,Working!$E$2:$BL$2,S5) -> 20.770891 | L5: =K5/Inputs!$E$3*100 -> 3.4618151 | N5: Execution Date for ISA + 0.5 month | O5: =SUMIFS(Working!$E$81:$BL$81,Working!$E$2:$BL$2,S5)+SUMIFS(Working!$E$413:$BL$413,Working!$E$2:$BL$2,S5) -> 20.770891 | P5: =O5/Inputs!$E$3*100 -> 3.4618151 | R5: =K5-O5 -> 0 | S5: =EOMONTH(S6,-6) -> 44834
B6: CUF | C6: =Inputs!C5 -> % | D6: =Inputs!E5 -> 0.2494 | F6: Road, Building & other civil | G6: =(Capex!I14+Capex!I19)/100 -> 25.425 | H6: =ROUND(G6*100/$D$5,3) -> 4.238 | J6: Execution Date for ISA + 6 month | K6: =SUMIFS(Working!$E$81:$BL$81,Working!$E$2:$BL$2,S6)+SUMIFS(Working!$E$413:$BL$413,Working!$E$2:$BL$2,S6) -> 24.232706 | L6: =K6/Inputs!$E$3*100 -> 4.0387843 | N6: Execution Date for ISA + 6 month | O6: =SUMIFS(Working!$E$81:$BL$81,Working!$E$2:$BL$2,S6)+SUMIFS(Working!$E$413:$BL$413,Working!$E$2:$BL$2,S6) -> 24.232706 | P6: =O6/Inputs!$E$3*100 -> 4.0387843 | R6: =K6-O6 -> 0 | S6: =EOMONTH(S7,-6) -> 45016
B7: Energy | C7: =Inputs!C6 -> MU | D7: =Inputs!E6 -> 1310.8464 | F7: Evacuation - Sub-station | G7: =(Capex!I26)/100 -> 116.8 | H7: =ROUND(G7*100/$D$5,3) -> 19.467 | J7: Execution Date for ISA + 12 months | K7: =SUMIFS(Working!$E$81:$BL$81,Working!$E$2:$BL$2,S7)+SUMIFS(Working!$E$413:$BL$413,Working!$E$2:$BL$2,S7) -> 40.040026 | L7: =K7/Inputs!$E$3*100 -> 6.6733377 | N7: Execution Date for ISA + 12 months | O7: =SUMIFS(Working!$E$81:$BL$81,Working!$E$2:$BL$2,S7)+SUMIFS(Working!$E$413:$BL$413,Working!$E$2:$BL$2,S7) -> 40.040026 | P7: =O7/Inputs!$E$3*100 -> 6.6733377 | R7: =K7-O7 -> 0 | S7: =EOMONTH(S10,-6) -> 45199
B8: Park COD | C8: =Inputs!C41 -> Date | D8: =Inputs!E41 -> 45200 | F8: Evacuation - Transmission Line | G8: =(Capex!I32)/100 -> 104.31453 | H8: =ROUND(G8*100/$D$5,3) -> 17.386
B9: Life of Project | C9: =Inputs!C42 -> Years | D9: =Inputs!E42 -> 25 | F9: Other Costs | G9: =(Capex!$I$53)/100 -> 63.066421 | H9: =ROUND(G9*100/$D$5,3) -> 10.511 | J9: Half Yearly Charges (Rs Cr) | N9: Half Yearly Charges (Rs Cr)
F10: Base Cost Total | G10: =SUM(G5:G9) -> 311.31121 | H10: =ROUND(G10*100/$D$5,2) -> 51.89 | J10: Project CoD + 1 day | K10: =SUMIFS(Working!$E$413:$BL$413,Working!$E$2:$BL$2,S10)-SUMIFS(Working!$E$408:$BL$408,Working!$E$2:$BL$2,S10) -> 5.4491489 | L10: =K10/Inputs!$E$3*100 -> 0.90819149 | N10: Project CoD + 1 day | O10: =$K10-SUMIFS(Working!$E$303:$BL$303,Working!$E$2:$BL$2,S10) -> 4.8636089 | P10: =O10/Inputs!$E$3*100 -> 0.81060148 | R10: =K10-O10 -> 0.58554004 | S10: =Inputs!E46 -> 45382 | U10: ="FY "&RIGHT(V10,2) -> FY 24 | V10: {=TRANSPOSE(Working!I1:BG1)} -> 2024 | W10: {=TRANSPOSE(Working!I380:BG380)} -> 0
B11: Financing | F11: Contingency & Insurance Charges | G11: =(Capex!I58)/100 -> 9.1237087 | H11: =ROUND(G11*100/$D$5,3) -> 1.521 | J11: Project CoD + 0.5 years + 1 day | K11: =SUMIFS(Working!$E$413:$BL$413,Working!$E$2:$BL$2,S11)-SUMIFS(Working!$E$408:$BL$408,Working!$E$2:$BL$2,S11) -> 9.8409561 | L11: =K11/Inputs!$E$3*100 -> 1.6401593 | N11: Project CoD + 0.5 years + 1 day | O11: =$K11-SUMIFS(Working!$E$303:$BL$303,Working!$E$2:$BL$2,S11) -> 9.2409561 | P11: =O11/Inputs!$E$3*100 -> 1.5401593 | R11: =K11-O11 -> 0.6 | S11: =EOMONTH(S10,6) -> 45565 | U11: ="FY "&RIGHT(V11,2) -> FY 24 | V11: 2024 | W11: 3
B12: =Inputs!B51 -> Moratorium Period (from start of operations) | C12: =Inputs!C51 -> Years | D12: =Inputs!E51 -> 1 | F12: Capital Expenditure | G12: =G10+G11 -> 320.43492 | H12: =H10+H11 -> 53.411 | J12: Project CoD + 1 years + 1 day | K12: =SUMIFS(Working!$E$413:$BL$413,Working!$E$2:$BL$2,S12)-SUMIFS(Working!$E$408:$BL$408,Working!$E$2:$BL$2,S12) -> 21.846455 | L12: =K12/Inputs!$E$3*100 -> 3.6410759 | N12: Project CoD + 1 years + 1 day | O12: =$K12-SUMIFS(Working!$E$303:$BL$303,Working!$E$2:$BL$2,S12) -> 21.231638 | P12: =O12/Inputs!$E$3*100 -> 3.5386064 | R12: =K12-O12 -> 0.61481705 | S12: =EOMONTH(S11,6) -> 45747 | U12: ="FY "&RIGHT(V12,2) -> FY 25 | V12: 2025 | W12: 3
B13: =Inputs!B52 -> Repayment Period | C13: =Inputs!C52 -> Years | D13: =Inputs!E52 -> 15 | F13: IDC | G13: =Working!$D$62 -> 9.2617535 | H13: =ROUND(G13/D5*10,3) -> 0.154 | J13: Project CoD + 1.5 years + 1 day | K13: =SUMIFS(Working!$E$413:$BL$413,Working!$E$2:$BL$2,S13)-SUMIFS(Working!$E$408:$BL$408,Working!$E$2:$BL$2,S13) -> 14.955944 | L13: =K13/Inputs!$E$3*100 -> 2.4926573 | N13: Project CoD + 1.5 years + 1 day | O13: =$K13-SUMIFS(Working!$E$303:$BL$303,Working!$E$2:$BL$2,S13) -> 14.325944 | P13: =O13/Inputs!$E$3*100 -> 2.3876573 | R13: =K13-O13 -> 0.63 | S13: =EOMONTH(S12,6) -> 45930 | U13: ="FY "&RIGHT(V13,2) -> FY 25 | V13: 2025 | W13: 3
B14: =Inputs!B53 -> Interest Rate | C14: =Inputs!C53 -> % | D14: =Inputs!E53 -> 0.08 | F14: Capex including IDC | G14: =G12+G13 -> 329.69667 | H14: =H12+H13 -> 53.565 | J14: Project CoD + 2 years + 1 day | K14: =SUMIFS(Working!$E$413:$BL$413,Working!$E$2:$BL$2,S14)-SUMIFS(Working!$E$408:$BL$408,Working!$E$2:$BL$2,S14) -> 15.116414 | L14: =K14/Inputs!$E$3*100 -> 2.5194024 | N14: Project CoD + 2 years + 1 day | O14: =$K14-SUMIFS(Working!$E$303:$BL$303,Working!$E$2:$BL$2,S14) -> 14.470856 | P14: =O14/Inputs!$E$3*100 -> 2.4118094 | R14: =K14-O14 -> 0.6455579 | S14: =EOMONTH(S13,6) -> 46112 | U14: ="FY "&RIGHT(V14,2) -> FY 26 | V14: 2026 | W14: 3
J15: Project CoD + 2.5 years + 1 day | K15: =SUMIFS(Working!$E$413:$BL$413,Working!$E$2:$BL$2,S15)-SUMIFS(Working!$E$408:$BL$408,Working!$E$2:$BL$2,S15) -> 14.969877 | L15: =K15/Inputs!$E$3*100 -> 2.4949795 | N15: Project CoD + 2.5 years + 1 day | O15: =$K15-SUMIFS(Working!$E$303:$BL$303,Working!$E$2:$BL$2,S15) -> 14.308377 | P15: =O15/Inputs!$E$3*100 -> 2.3847295 | R15: =K15-O15 -> 0.6615 | S15: =EOMONTH(S14,6) -> 46295 | U15: ="FY "&RIGHT(V15,2) -> FY 26 | V15: 2026 | W15: 3
B16: Return | F16: Financing | G16: Rs Crore | J16: Project CoD + 3 years + 1 day | K16: =SUMIFS(Working!$E$413:$BL$413,Working!$E$2:$BL$2,S16)-SUMIFS(Working!$E$408:$BL$408,Working!$E$2:$BL$2,S16) -> 14.838376 | L16: =K16/Inputs!$E$3*100 -> 2.4730627 | N16: Project CoD + 3 years + 1 day | O16: =$K16-SUMIFS(Working!$E$303:$BL$303,Working!$E$2:$BL$2,S16) -> 14.160541 | P16: =O16/Inputs!$E$3*100 -> 2.3600901 | R16: =K16-O16 -> 0.67783579 | S16: =EOMONTH(S15,6) -> 46477 | U16: ="FY "&RIGHT(V16,2) -> FY 27 | V16: 2027 | W16: 3
B17: =Inputs!B61 -> Return on Equity (RoE) - Post Tax | C17: % | D17: =Inputs!E61 -> 0 | F17: Commerical Loan 1 | G17: =Working!D65 -> 161.55137 | H17: =G17/$G$24 -> 0.49 | I17: 162.02 | J17: Project CoD + 3.5 years + 1 day | K17: =SUMIFS(Working!$E$413:$BL$413,Working!$E$2:$BL$2,S17)-SUMIFS(Working!$E$408:$BL$408,Working!$E$2:$BL$2,S17) -> 14.70785 | L17: =K17/Inputs!$E$3*100 -> 2.4513084 | N17: Project CoD + 3.5 years + 1 day | O17: =$K17-SUMIFS(Working!$E$303:$BL$303,Working!$E$2:$BL$2,S17) -> 14.013275 | P17: =O17/Inputs!$E$3*100 -> 2.3355459 | R17: =K17-O17 -> 0.694575 | S17: =EOMONTH(S16,6) -> 46660 | U17: ="FY "&RIGHT(V17,2) -> FY 27 | V17: 2027 | W17: 3
F18: Commerical Loan 2 | G18: =Working!D66 -> 0 | H18: =G18/$G$24 -> 0 | J18: Project CoD + 4 years + 1 day | K18: =SUMIFS(Working!$E$413:$BL$413,Working!$E$2:$BL$2,S18)-SUMIFS(Working!$E$408:$BL$408,Working!$E$2:$BL$2,S18) -> 14.578947 | L18: =K18/Inputs!$E$3*100 -> 2.4298244 | N18: Project CoD + 4 years + 1 day | O18: =$K18-SUMIFS(Working!$E$303:$BL$303,Working!$E$2:$BL$2,S18) -> 13.867219 | P18: =O18/Inputs!$E$3*100 -> 2.3112032 | R18: =K18-O18 -> 0.71172758 | S18: =EOMONTH(S17,6) -> 46843 | U18: ="FY "&RIGHT(V18,2) -> FY 28 | V18: 2028 | W18: 3
B19: Working Capital | F19: Grant/ Capital Subsidy | G19: =Working!D67+Working!D70 -> 98.909002 | H19: =G19/$G$24 -> 0.3 | I19: =G19-G20 -> 114.71632 | J19: Project CoD + 4.5 years + 1 day | K19: =SUMIFS(Working!$E$413:$BL$413,Working!$E$2:$BL$2,S19)-SUMIFS(Working!$E$408:$BL$408,Working!$E$2:$BL$2,S19) -> 14.45167 | L19: =K19/Inputs!$E$3*100 -> 2.4086117 | N19: Project CoD + 4.5 years + 1 day | O19: =$K19-SUMIFS(Working!$E$303:$BL$303,Working!$E$2:$BL$2,S19) -> 13.722366 | P19: =O19/Inputs!$E$3*100 -> 2.2870611 | R19: =K19-O19 -> 0.72930375 | S19: =EOMONTH(S18,6) -> 47026 | U19: ="FY "&RIGHT(V19,2) -> FY 28 | V19: 2028 | W19: 3
B20: =Inputs!B79 -> Receivables | C20: =Inputs!C79 -> Months | D20: =Inputs!E79 -> 1 | F20: Deferred Capital Subisdy | G20: =-Working!D70 -> -15.807321 | H20: =G20/$G$24 -> -0.047945041 | J20: Project CoD + 5 years + 1 day | K20: =SUMIFS(Working!$E$413:$BL$413,Working!$E$2:$BL$2,S20)-SUMIFS(Working!$E$408:$BL$408,Working!$E$2:$BL$2,S20) -> 14.326055 | L20: =K20/Inputs!$E$3*100 -> 2.3876758 | N20: Project CoD + 5 years + 1 day | O20: =$K20-SUMIFS(Working!$E$303:$BL$303,Working!$E$2:$BL$2,S20) -> 13.578741 | P20: =O20/Inputs!$E$3*100 -> 2.2631235 | R20: =K20-O20 -> 0.74731396 | S20: =EOMONTH(S19,6) -> 47208 | U20: ="FY "&RIGHT(V20,2) -> FY 29 | V20: 2029 | W20: 3
B21: =Inputs!B80 -> O&M | C21: =Inputs!C80 -> Months | D21: =Inputs!E80 -> 1 | F21: Equity | G21: =Working!D68 -> 0 | H21: =G21/$G$24 -> 0 | I21: =G24-I17-I19 -> 52.960352 | J21: Project CoD + 5.5 years + 1 day | K21: =SUMIFS(Working!$E$413:$BL$413,Working!$E$2:$BL$2,S21)-SUMIFS(Working!$E$408:$BL$408,Working!$E$2:$BL$2,S21) -> 14.212371 | L21: =K21/Inputs!$E$3*100 -> 2.3687286 | N21: Project CoD + 5.5 years + 1 day | O21: =$K21-SUMIFS(Working!$E$303:$BL$303,Working!$E$2:$BL$2,S21) -> 13.446602 | P21: =O21/Inputs!$E$3*100 -> 2.2411004 | R21: =K21-O21 -> 0.76576894 | S21: =EOMONTH(S20,6) -> 47391 | U21: ="FY "&RIGHT(V21,2) -> FY 29 | V21: 2029 | W21: 3
B22: =Inputs!B81 -> Maintenance spares | C22: =Inputs!C81 -> % | D22: =Inputs!E81 -> 0 | F22: Developer Contribution - Upfront | G22: =Working!D69+IF(Inputs!$E$66,Working!D70,0) -> 85.043622 | H22: =G22/$G$24 -> 0.25794504 | J22: Project CoD + 6 years + 1 day | K22: =SUMIFS(Working!$E$413:$BL$413,Working!$E$2:$BL$2,S22)-SUMIFS(Working!$E$408:$BL$408,Working!$E$2:$BL$2,S22) -> 14.089664 | L22: =K22/Inputs!$E$3*100 -> 2.3482773 | N22: Project CoD + 6 years + 1 day | O22: =$K22-SUMIFS(Working!$E$303:$BL$303,Working!$E$2:$BL$2,S22) -> 13.304984 | P22: =O22/Inputs!$E$3*100 -> 2.2174974 | R22: =K22-O22 -> 0.78467966 | S22: =EOMONTH(S21,6) -> 47573 | U22: ="FY "&RIGHT(V22,2) -> FY 30 | V22: 2030 | W22: 3
B23: =Inputs!B82 -> IOWC | C23: =Inputs!C82 -> % | D23: =Inputs!E82 -> 0.1 | F23: Additional Loan | G23: =IF(Inputs!$E$66,0,Working!D70) -> 0 | H23: =G23/$G$24 -> 0 | J23: Project CoD + 6.5 years + 1 day | K23: =SUMIFS(Working!$E$413:$BL$413,Working!$E$2:$BL$2,S23)-SUMIFS(Working!$E$408:$BL$408,Working!$E$2:$BL$2,S23) -> 13.969293 | L23: =K23/Inputs!$E$3*100 -> 2.3282155 | N23: Project CoD + 6.5 years + 1 day | O23: =$K23-SUMIFS(Working!$E$303:$BL$303,Working!$E$2:$BL$2,S23) -> 13.165235 | P23: =O23/Inputs!$E$3*100 -> 2.1942059 | R23: =K23-O23 -> 0.80405738 | S23: =EOMONTH(S22,6) -> 47756 | U23: ="FY "&RIGHT(V23,2) -> FY 30 | V23: 2030 | W23: 3
B24: =Inputs!B83 -> Margin Money for WC | C24: =Inputs!C83 -> % | D24: =Inputs!E83 -> 0.25 | F24: Total | G24: =SUM(G17:G23) -> 329.69667 | H24: =SUM(H17:H23) -> 1 | J24: Project CoD + 7 years + 1 day | K24: =SUMIFS(Working!$E$413:$BL$413,Working!$E$2:$BL$2,S24)-SUMIFS(Working!$E$408:$BL$408,Working!$E$2:$BL$2,S24) -> 13.85069 | L24: =K24/Inputs!$E$3*100 -> 2.3084483 | N24: Project CoD + 7 years + 1 day | O24: =$K24-SUMIFS(Working!$E$303:$BL$303,Working!$E$2:$BL$2,S24) -> 13.026776 | P24: =O24/Inputs!$E$3*100 -> 2.1711293 | R24: =K24-O24 -> 0.82391364 | S24: =EOMONTH(S23,6) -> 47938 | U24: ="FY "&RIGHT(V24,2) -> FY 31 | V24: 2031 | W24: 3
H25: =G22-SUM(K5:K7) -> 0 | J25: Project CoD + 7.5 years + 1 day | K25: =SUMIFS(Working!$E$413:$BL$413,Working!$E$2:$BL$2,S25)-SUMIFS(Working!$E$408:$BL$408,Working!$E$2:$BL$2,S25) -> 13.733922 | L25: =K25/Inputs!$E$3*100 -> 2.2889871 | N25: Project CoD + 7.5 years + 1 day | O25: =$K25-SUMIFS(Working!$E$303:$BL$303,Working!$E$2:$BL$2,S25) -> 12.889662 | P25: =O25/Inputs!$E$3*100 -> 2.148277 | R25: =K25-O25 -> 0.84426025 | S25: =EOMONTH(S24,6) -> 48121 | U25: ="FY "&RIGHT(V25,2) -> FY 31 | V25: 2031 | W25: 3
J26: Project CoD + 8 years + 1 day | K26: =SUMIFS(Working!$E$413:$BL$413,Working!$E$2:$BL$2,S26)-SUMIFS(Working!$E$408:$BL$408,Working!$E$2:$BL$2,S26) -> 13.619026 | L26: =K26/Inputs!$E$3*100 -> 2.2698377 | N26: Project CoD + 8 years + 1 day | O26: =$K26-SUMIFS(Working!$E$303:$BL$303,Working!$E$2:$BL$2,S26) -> 12.753917 | P26: =O26/Inputs!$E$3*100 -> 2.1256528 | R26: =K26-O26 -> 0.86510933 | S26: =EOMONTH(S25,6) -> 48304 | U26: ="FY "&RIGHT(V26,2) -> FY 32 | V26: 2032 | W26: 3
B27: Tariff Assumptions | F27: Park Infrastructure Cost Breakup | G27: Share | J27: Project CoD + 8.5 years + 1 day | K27: =SUMIFS(Working!$E$413:$BL$413,Working!$E$2:$BL$2,S27)-SUMIFS(Working!$E$408:$BL$408,Working!$E$2:$BL$2,S27) -> 13.506039 | L27: =K27/Inputs!$E$3*100 -> 2.2510065 | N27: Project CoD + 8.5 years + 1 day | O27: =$K27-SUMIFS(Working!$E$303:$BL$303,Working!$E$2:$BL$2,S27) -> 12.619566 | P27: =O27/Inputs!$E$3*100 -> 2.1032609 | R27: =K27-O27 -> 0.88647327 | S27: =EOMONTH(S26,6) -> 48487 | U27: ="FY "&RIGHT(V27,2) -> FY 32 | V27: 2032 | W27: 3
B28: =Inputs!E94 -> Option2 | D28: Yearly Tariff | F28: Land | G28: =H5/$H$14 -> 0.0053019696 | J28: Project CoD + 9 years + 1 day | K28: =SUMIFS(Working!$E$413:$BL$413,Working!$E$2:$BL$2,S28)-SUMIFS(Working!$E$408:$BL$408,Working!$E$2:$BL$2,S28) -> 13.394998 | L28: =K28/Inputs!$E$3*100 -> 2.2324997 | N28: Project CoD + 9 years + 1 day | O28: =$K28-SUMIFS(Working!$E$303:$BL$303,Working!$E$2:$BL$2,S28) -> 12.486634 | P28: =O28/Inputs!$E$3*100 -> 2.0811056 | R28: =K28-O28 -> 0.90836479 | S28: =EOMONTH(S27,6) -> 48669 | U28: ="FY "&RIGHT(V28,2) -> FY 33 | V28: 2033 | W28: 3
F29: Road, Building & other civil | G29: =H6/$H$14 -> 0.079118828 | J29: Project CoD + 9.5 years + 1 day | K29: =SUMIFS(Working!$E$413:$BL$413,Working!$E$2:$BL$2,S29)-SUMIFS(Working!$E$408:$BL$408,Working!$E$2:$BL$2,S29) -> 13.285944 | L29: =K29/Inputs!$E$3*100 -> 2.214324 | N29: Project CoD + 9.5 years + 1 day | O29: =$K29-SUMIFS(Working!$E$303:$BL$303,Working!$E$2:$BL$2,S29) -> 12.355147 | P29: =O29/Inputs!$E$3*100 -> 2.0591912 | R29: =K29-O29 -> 0.93079693 | S29: =EOMONTH(S28,6) -> 48852 | U29: ="FY "&RIGHT(V29,2) -> FY 33 | V29: 2033 | W29: 3
B30: COD Date | D30: 45139 | F30: Sub-station | G30: =H7/$H$14 -> 0.36342761 | J30: Project CoD + 10 years + 1 day | K30: =SUMIFS(Working!$E$413:$BL$413,Working!$E$2:$BL$2,S30)-SUMIFS(Working!$E$408:$BL$408,Working!$E$2:$BL$2,S30) -> 13.178915 | L30: =K30/Inputs!$E$3*100 -> 2.1964858 | N30: Project CoD + 10 years + 1 day | O30: =$K30-SUMIFS(Working!$E$303:$BL$303,Working!$E$2:$BL$2,S30) -> 12.225132 | P30: =O30/Inputs!$E$3*100 -> 2.037522 | R30: =K30-O30 -> 0.95378303 | S30: =EOMONTH(S29,6) -> 49034 | U30: ="FY "&RIGHT(V30,2) -> FY 34 | V30: 2034 | W30: 3
F31: Transmission | G31: =H8/$H$14 -> 0.32457762 | J31: Project CoD + 10.5 years + 1 day | K31: =SUMIFS(Working!$E$413:$BL$413,Working!$E$2:$BL$2,S31)-SUMIFS(Working!$E$408:$BL$408,Working!$E$2:$BL$2,S31) -> 13.073953 | L31: =K31/Inputs!$E$3*100 -> 2.1789921 | N31: Project CoD + 10.5 years + 1 day | O31: =$K31-SUMIFS(Working!$E$303:$BL$303,Working!$E$2:$BL$2,S31) -> 12.096616 | P31: =O31/Inputs!$E$3*100 -> 2.0161026 | R31: =K31-O31 -> 0.97733678 | S31: =EOMONTH(S30,6) -> 49217 | U31: ="FY "&RIGHT(V31,2) -> FY 34 | V31: 2034 | W31: 3
F32: Other Costs | G32: =H9/$H$14 -> 0.19622888 | J32: Project CoD + 11 years + 1 day | K32: =SUMIFS(Working!$E$413:$BL$413,Working!$E$2:$BL$2,S32)-SUMIFS(Working!$E$408:$BL$408,Working!$E$2:$BL$2,S32) -> 12.971098 | L32: =K32/Inputs!$E$3*100 -> 2.1618497 | N32: Project CoD + 11 years + 1 day | O32: =$K32-SUMIFS(Working!$E$303:$BL$303,Working!$E$2:$BL$2,S32) -> 11.969626 | P32: =O32/Inputs!$E$3*100 -> 1.9949376 | R32: =K32-O32 -> 1.0014722 | S32: =EOMONTH(S31,6) -> 49399 | U32: ="FY "&RIGHT(V32,2) -> FY 35 | V32: 2035 | W32: 3
F33: Contingency & Insurance Charges | G33: =H11/$H$14 -> 0.028395407 | J33: Project CoD + 11.5 years + 1 day | K33: =SUMIFS(Working!$E$413:$BL$413,Working!$E$2:$BL$2,S33)-SUMIFS(Working!$E$408:$BL$408,Working!$E$2:$BL$2,S33) -> 12.870394 | L33: =K33/Inputs!$E$3*100 -> 2.1450656 | N33: Project CoD + 11.5 years + 1 day | O33: =$K33-SUMIFS(Working!$E$303:$BL$303,Working!$E$2:$BL$2,S33) -> 11.84419 | P33: =O33/Inputs!$E$3*100 -> 1.9740317 | R33: =K33-O33 -> 1.0262036 | S33: =EOMONTH(S32,6) -> 49582 | U33: ="FY "&RIGHT(V33,2) -> FY 35 | V33: 2035 | W33: 3
F34: Total | G34: =SUM(G28:G33) -> 0.99705031 | J34: Project CoD + 12 years + 1 day | K34: =SUMIFS(Working!$E$413:$BL$413,Working!$E$2:$BL$2,S34)-SUMIFS(Working!$E$408:$BL$408,Working!$E$2:$BL$2,S34) -> 12.771883 | L34: =K34/Inputs!$E$3*100 -> 2.1286471 | N34: Project CoD + 12 years + 1 day | O34: =$K34-SUMIFS(Working!$E$303:$BL$303,Working!$E$2:$BL$2,S34) -> 11.720337 | P34: =O34/Inputs!$E$3*100 -> 1.9533895 | R34: =K34-O34 -> 1.0515458 | S34: =EOMONTH(S33,6) -> 49765 | U34: ="FY "&RIGHT(V34,2) -> FY 36 | V34: 2036 | W34: 3
F35: IDC | G35: =H13/$H$14 -> 0.0028750117 | J35: Project CoD + 12.5 years + 1 day | K35: =SUMIFS(Working!$E$413:$BL$413,Working!$E$2:$BL$2,S35)-SUMIFS(Working!$E$408:$BL$408,Working!$E$2:$BL$2,S35) -> 12.675609 | L35: =K35/Inputs!$E$3*100 -> 2.1126016 | N35: Project CoD + 12.5 years + 1 day | O35: =$K35-SUMIFS(Working!$E$303:$BL$303,Working!$E$2:$BL$2,S35) -> 11.598096 | P35: =O35/Inputs!$E$3*100 -> 1.9330159 | R35: =K35-O35 -> 1.0775138 | S35: =EOMONTH(S34,6) -> 49948 | U35: ="FY "&RIGHT(V35,2) -> FY 36 | V35: 2036 | W35: 3
F36: Grand Total | G36: =H14/$H$14 -> 1 | J36: Project CoD + 13 years + 1 day | K36: =SUMIFS(Working!$E$413:$BL$413,Working!$E$2:$BL$2,S36)-SUMIFS(Working!$E$408:$BL$408,Working!$E$2:$BL$2,S36) -> 12.581618 | L36: =K36/Inputs!$E$3*100 -> 2.0969364 | N36: Project CoD + 13 years + 1 day | O36: =$K36-SUMIFS(Working!$E$303:$BL$303,Working!$E$2:$BL$2,S36) -> 11.477495 | P36: =O36/Inputs!$E$3*100 -> 1.9129159 | R36: =K36-O36 -> 1.1041231 | S36: =EOMONTH(S35,6) -> 50130 | U36: ="FY "&RIGHT(V36,2) -> FY 37 | V36: 2037 | W36: 3
J37: Project CoD + 13.5 years + 1 day | K37: =SUMIFS(Working!$E$413:$BL$413,Working!$E$2:$BL$2,S37)-SUMIFS(Working!$E$408:$BL$408,Working!$E$2:$BL$2,S37) -> 13.405535 | L37: =K37/Inputs!$E$3*100 -> 2.2342559 | N37: Project CoD + 13.5 years + 1 day | O37: =$K37-SUMIFS(Working!$E$303:$BL$303,Working!$E$2:$BL$2,S37) -> 12.274146 | P37: =O37/Inputs!$E$3*100 -> 2.0456909 | R37: =K37-O37 -> 1.1313895 | S37: =EOMONTH(S36,6) -> 50313 | U37: ="FY "&RIGHT(V37,2) -> FY 37 | V37: 2037 | W37: 3
F38: Other Charges - Breakup | G38: Rs Crore | H38: Rs Lakh per MW | J38: Project CoD + 14 years + 1 day | K38: =SUMIFS(Working!$E$413:$BL$413,Working!$E$2:$BL$2,S38)-SUMIFS(Working!$E$408:$BL$408,Working!$E$2:$BL$2,S38) -> 13.267436 | L38: =K38/Inputs!$E$3*100 -> 2.2112393 | N38: Project CoD + 14 years + 1 day | O38: =$K38-SUMIFS(Working!$E$303:$BL$303,Working!$E$2:$BL$2,S38) -> 12.108107 | P38: =O38/Inputs!$E$3*100 -> 2.0180178 | R38: =K38-O38 -> 1.1593292 | S38: =EOMONTH(S37,6) -> 50495 | U38: ="FY "&RIGHT(V38,2) -> FY 38 | V38: 2038 | W38: 3
F39: PMC Cost - Transmission | G39: =Capex!I35/100 -> 17.689163 | H39: =Capex!J35 -> 2.95 | J39: Project CoD + 14.5 years + 1 day | K39: =SUMIFS(Working!$E$413:$BL$413,Working!$E$2:$BL$2,S39)-SUMIFS(Working!$E$408:$BL$408,Working!$E$2:$BL$2,S39) -> 13.183174 | L39: =K39/Inputs!$E$3*100 -> 2.1971957 | N39: Project CoD + 14.5 years + 1 day | O39: =$K39-SUMIFS(Working!$E$303:$BL$303,Working!$E$2:$BL$2,S39) -> 11.995215 | P39: =O39/Inputs!$E$3*100 -> 1.9992025 | R39: =K39-O39 -> 1.187959 | S39: =EOMONTH(S38,6) -> 50678 | U39: ="FY "&RIGHT(V39,2) -> FY 38 | V39: 2038 | W39: 3
F40: PMC charges to MPUVNL - Upfront | G40: =Capex!I36/100 -> 0 | H40: =Capex!J40 -> 0.07 | J40: Project CoD + 15 years + 1 day | K40: =SUMIFS(Working!$E$413:$BL$413,Working!$E$2:$BL$2,S40)-SUMIFS(Working!$E$408:$BL$408,Working!$E$2:$BL$2,S40) -> 13.098643 | L40: =K40/Inputs!$E$3*100 -> 2.1831071 | N40: Project CoD + 15 years + 1 day | O40: =$K40-SUMIFS(Working!$E$303:$BL$303,Working!$E$2:$BL$2,S40) -> 11.881347 | P40: =O40/Inputs!$E$3*100 -> 1.9802245 | R40: =K40-O40 -> 1.2172957 | S40: =EOMONTH(S39,6) -> 50860 | U40: ="FY "&RIGHT(V40,2) -> FY 39 | V40: 2039 | W40: 3
...

Sheet Interest Rate Assessment
F1: 0.095
C2: Upfront Charges Assessment | D2: Unit | E2: Total Value | F2: Net Present Value | G2: Execution Date for ISA + 0.5 month | H2: Execution Date for ISA + 6 month | I2: Execution Date for ISA + 12 months | J2: Project CoD + 1 day | K2: Project CoD + 0.5 years + 1 day | L2: Project CoD + 1 years + 1 day | M2: Project CoD + 1.5 years + 1 day | N2: Project CoD + 2 years + 1 day | O2: Project CoD + 2.5 years + 1 day | P2: Project CoD + 3 years + 1 day | Q2: Project CoD + 3.5 years + 1 day | R2: Project CoD + 4 years + 1 day | S2: Project CoD + 4.5 years + 1 day | T2: Project CoD + 5 years + 1 day | U2: Project CoD + 5.5 years + 1 day | V2: Project CoD + 6 years + 1 day | W2: Project CoD + 6.5 years + 1 day | X2: Project CoD + 7 years + 1 day | Y2: Project CoD + 7.5 years + 1 day | Z2: Project CoD + 8 years + 1 day | AA2: Project CoD + 8.5 years + 1 day | AB2: Project CoD + 9 years + 1 day | AC2: Project CoD + 9.5 years + 1 day | AD2: Project CoD + 10 years + 1 day | AE2: Project CoD + 10.5 years + 1 day | AF2: Project CoD + 11 years + 1 day | AG2: Project CoD + 11.5 years + 1 day | AH2: Project CoD + 12 years + 1 day | AI2: Project CoD + 12.5 years + 1 day | AJ2: Project CoD + 13 years + 1 day | AK2: Project CoD + 13.5 years + 1 day | AL2: Project CoD + 14 years + 1 day | AM2: Project CoD + 14.5 years + 1 day | AN2: Project CoD + 15 years + 1 day | AO2: Project CoD + 15.5 years + 1 day | AP2: Project CoD + 16 years + 1 day | AQ2: Project CoD + 16.5 years + 1 day | AR2: Project CoD + 17 years + 1 day | AS2: Project CoD + 17.5 years + 1 day | AT2: Project CoD + 18 years + 1 day | AU2: Project CoD + 18.5 years + 1 day | AV2: Project CoD + 19 years + 1 day | AW2: Project CoD + 19.5 years + 1 day | AX2: Project CoD + 20 years + 1 day | AY2: Project CoD + 20.5 years + 1 day | AZ2: Project CoD + 21 years + 1 day | BA2: Project CoD + 21.5 years + 1 day | BB2: Project CoD + 22 years + 1 day | BC2: Project CoD + 22.5 years + 1 day | BD2: Project CoD + 23 years + 1 day | BE2: Project CoD + 23.5 years + 1 day | BF2: Project CoD + 24 years + 1 day | BG2: Project CoD + 24.5 years + 1 day | BH2: Project CoD + 25 years
B3: A | C3: Base Case | D3: Rs Cr. | E3: =SUM(G3:BH3) -> 663.87665 | F3: =NPV($F$1,G3:BH3) -> 175.60222 | G3: 20.770891 | H3: 24.232706 | I3: 40.040026 | J3: 5.4491489 | K3: 9.8409561 | L3: 21.846455 | M3: 14.955944 | N3: 15.116414 | O3: 14.969877 | P3: 14.838376 | Q3: 14.70785 | R3: 14.578947 | S3: 14.45167 | T3: 14.326055 | U3: 14.212371 | V3: 14.089664 | W3: 13.969293 | X3: 13.85069 | Y3: 13.733922 | Z3: 13.619026 | AA3: 13.506039 | AB3: 13.394998 | AC3: 13.285944 | AD3: 13.178915 | AE3: 13.073953 | AF3: 12.971098 | AG3: 12.870394 | AH3: 12.771883 | AI3: 12.675609 | AJ3: 12.581618 | AK3: 13.405535 | AL3: 13.267436 | AM3: 13.183174 | AN3: 13.098643 | AO3: 6.4447953 | AP3: 7.101025 | AQ3: 7.2138322 | AR3: 7.3532128 | AS3: 7.494278 | AT3: 7.6381746 | AU3: 7.784911 | AV3: 7.9345467 | AW3: 8.0871404 | AX3: 8.2427518 | AY3: 8.401442 | AZ3: 8.5632733 | BA3: 8.7283094 | BB3: 8.8966151 | BC3: 9.0682569 | BD3: 9.2433023 | BE3: 9.4218203 | BF3: 9.6038816 | BG3: 9.789558 | BH3: 0
D4: Rs Lakhs/MW | E4: =SUM(G4:BH4) -> 110.64611 | F4: =NPV($F$1,G4:BH4) -> 29.267036 | G4: 3.4618151 | H4: 4.0387843 | I4: 6.6733377 | J4: 0.90819149 | K4: 1.6401593 | L4: 3.6410759 | M4: 2.4926573 | N4: 2.5194024 | O4: 2.4949795 | P4: 2.4730627 | Q4: 2.4513084 | R4: 2.4298244 | S4: 2.4086117 | T4: 2.3876758 | U4: 2.3687286 | V4: 2.3482773 | W4: 2.3282155 | X4: 2.3084483 | Y4: 2.2889871 | Z4: 2.2698377 | AA4: 2.2510065 | AB4: 2.2324997 | AC4: 2.214324 | AD4: 2.1964858 | AE4: 2.1789921 | AF4: 2.1618497 | AG4: 2.1450656 | AH4: 2.1286471 | AI4: 2.1126016 | AJ4: 2.0969364 | AK4: 2.2342559 | AL4: 2.2112393 | AM4: 2.1971957 | AN4: 2.1831071 | AO4: 1.0741326 | AP4: 1.1835042 | AQ4: 1.2023054 | AR4: 1.2255355 | AS4: 1.2490463 | AT4: 1.2730291 | AU4: 1.2974852 | AV4: 1.3224245 | AW4: 1.3478567 | AX4: 1.373792 | AY4: 1.4002403 | AZ4: 1.4272122 | BA4: 1.4547182 | BB4: 1.4827692 | BC4: 1.5113761 | BD4: 1.5405504 | BE4: 1.5703034 | BF4: 1.6006469 | BG4: 1.631593 | BH4: 0
B6: B | C6: Interest Rate - 9.5% & A&G - 0.20 lakh/MW | D6: Rs Cr. | E6: =SUM(G6:BH6) -> 687.05542 | F6: =NPV($F$1,G6:BH6) -> 184.0747 | G6: 20.883044 | H6: 24.363551 | I6: 40.327968 | J6: 8.1873064 | K6: 11.005074 | L6: 23.101681 | M6: 16.113413 | N6: 16.235173 | O6: 16.047342 | P6: 15.87466 | Q6: 15.702947 | R6: 15.532858 | S6: 15.364395 | T6: 15.197594 | U6: 15.033469 | V6: 14.870069 | W6: 14.708486 | X6: 14.548698 | Y6: 14.390745 | Z6: 14.234663 | AA6: 14.08049 | AB6: 13.928264 | AC6: 13.778023 | AD6: 13.629809 | AE6: 13.483661 | AF6: 13.33962 | AG6: 13.19773 | AH6: 13.058034 | AI6: 12.920575 | AJ6: 12.785398 | AK6: 13.573042 | AL6: 13.393495 | AM6: 13.268062 | AN6: 13.142344 | AO6: 13.019295 | AP6: 0.99282086 | AQ6: 7.4823382 | AR6: 7.3426565 | AS6: 7.4959404 | AT6: 7.6393083 | AU6: 7.7860738 | AV6: 7.9357143 | AW6: 8.0883139 | AX6: 8.2439311 | AY6: 8.4026272 | AZ6: 8.5644644 | BA6: 8.7295064 | BB6: 8.8978181 | BC6: 9.0694659 | BD6: 9.2445173 | BE6: 9.4230414 | BF6: 9.6051088 | BG6: 9.7907913 | BH6: 0
D7: Rs Lakhs/MW | E7: =SUM(G7:BH7) -> 114.50924 | F7: =NPV($F$1,G7:BH7) -> 30.679117 | G7: 3.4805073 | H7: 4.0605918 | I7: 6.721328 | J7: 1.3645511 | K7: 1.8341791 | L7: 3.8502801 | M7: 2.6855689 | N7: 2.7058622 | O7: 2.674557 | P7: 2.6457766 | Q7: 2.6171579 | R7: 2.5888096 | S7: 2.5607325 | T7: 2.5329323 | U7: 2.5055782 | V7: 2.4783449 | W7: 2.4514143 | X7: 2.424783 | Y7: 2.3984575 | Z7: 2.3724439 | AA7: 2.3467483 | AB7: 2.3213773 | AC7: 2.2963372 | AD7: 2.2716348 | AE7: 2.2472768 | AF7: 2.2232701 | AG7: 2.1996217 | AH7: 2.176339 | AI7: 2.1534291 | AJ7: 2.1308997 | AK7: 2.2621736 | AL7: 2.2322492 | AM7: 2.2113436 | AN7: 2.1903907 | AO7: 2.1698826 | AP7: 0.16547014 | AQ7: 1.2470564 | AR7: 1.2237761 | AS7: 1.2493234 | AT7: 1.273218 | AU7: 1.297679 | AV7: 1.3226191 | AW7: 1.3480523 | AX7: 1.3739885 | AY7: 1.4004379 | AZ7: 1.4274107 | BA7: 1.4549177 | BB7: 1.4829697 | BC7: 1.5115776 | BD7: 1.5407529 | BE7: 1.5705069 | BF7: 1.6008515 | BG7: 1.6317985 | BH7: 0
B9: C | C9: Interest Rate - 9.5% & A&G - 0.1 lakh/MW | D9: Rs Cr. | E9: =SUM(G9:BH9) -> 658.31672 | F9: =NPV($F$1,G9:BH9) -> 180.952 | G9: 20.883044 | H9: 24.363551 | I9: 40.327968 | J9: 7.8594408 | K9: 10.702039 | L9: 22.789571 | M9: 15.793819 | N9: 15.907677 | O9: 15.711758 | P9: 15.530789 | Q9: 15.350585 | R9: 15.171793 | S9: 14.994414 | T9: 14.818476 | U9: 14.644819 | V9: 14.471831 | W9: 14.300412 | X9: 14.130547 | Y9: 13.962268 | Z9: 13.795604 | AA9: 13.630589 | AB9: 13.467252 | AC9: 13.305627 | AD9: 13.145746 | AE9: 12.987644 | AF9: 12.831355 | AG9: 12.676913 | AH9: 12.524355 | AI9: 12.373717 | AJ9: 12.225036 | AK9: 12.998841 | AL9: 12.805114 | AM9: 12.665151 | AN9: 12.524544 | AO9: 12.386239 | AP9: 0.3444124 | AQ9: 6.817905 | AR9: 6.6618155 | AS9: 6.798286 | AT9: 6.9244252 | AU9: 7.0535367 | AV9: 7.1850872 | AW9: 7.3191499 | AX9: 7.4557726 | AY9: 7.595005 | AZ9: 7.7368979 | BA9: 7.8815031 | BB9: 8.0288734 | BC9: 8.1790624 | BD9: 8.3321253 | BE9: 8.4881178 | BF9: 8.6470971 | BG9: 8.8091215 | BH9: 0
D10: Rs Lakhs/MW | E10: =SUM(G10:BH10) -> 109.71945 | F10: =NPV($F$1,G10:BH10) -> 30.158667 | G10: 3.4805073 | H10: 4.0605918 | I10: 6.721328 | J10: 1.3099068 | K10: 1.7836731 | L10: 3.7982619 | M10: 2.6323032 | N10: 2.6512795 | O10: 2.6186264 | P10: 2.5884648 | Q10: 2.5584308 | R10: 2.5286322 | S10: 2.499069 | T10: 2.469746 | U10: 2.4408032 | V10: 2.4119718 | W10: 2.383402 | X10: 2.3550912 | Y10: 2.3270446 | Z10: 2.2992674 | AA10: 2.2717648 | AB10: 2.244542 | AC10: 2.2176045 | AD10: 2.1909577 | AE10: 2.1646074 | AF10: 2.1385592 | AG10: 2.1128189 | AH10: 2.0873925 | AI10: 2.0622861 | AJ10: 2.0375059 | AK10: 2.1664735 | AL10: 2.1341857 | AM10: 2.1108584 | AN10: 2.0874241 | AO10: 2.0643732 | AP10: 0.057402067 | AQ10: 1.1363175 | AR10: 1.1103026 | AS10: 1.1330477 | AT10: 1.1540709 | AU10: 1.1755894 | AV10: 1.1975145 | AW10: 1.2198583 | AX10: 1.2426288 | AY10: 1.2658342 | AZ10: 1.289483 | BA10: 1.3135839 | BB10: 1.3381456 | BC10: 1.3631771 | BD10: 1.3886875 | BE10: 1.4146863 | BF10: 1.4411829 | BG10: 1.4681869 | BH10: 0
B12: D | C12: Interest Rate - 9.5% & A&G - 0.0 lakh/MW | D12: Rs Cr. | E12: =SUM(G12:BH12) -> 629.57803 | F12: =NPV($F$1,G12:BH12) -> 177.8293 | G12: 20.883044 | H12: 24.363551 | I12: 40.327968 | J12: 7.5315753 | K12: 10.399003 | L12: 22.477462 | M12: 15.474225 | N12: 15.58018 | O12: 15.376175 | P12: 15.186918 | Q12: 14.998222 | R12: 14.810729 | S12: 14.624433 | T12: 14.439358 | U12: 14.256169 | V12: 14.073592 | W12: 13.892338 | X12: 13.712396 | Y12: 13.53379 | Z12: 13.356546 | AA12: 13.180687 | AB12: 13.00624 | AC12: 12.83323 | AD12: 12.661684 | AE12: 12.491628 | AF12: 12.32309 | AG12: 12.156096 | AH12: 11.990676 | AI12: 11.826859 | AJ12: 11.664673 | AK12: 12.42464 | AL12: 12.216734 | AM12: 12.06224 | AN12: 11.906745 | AO12: 11.753182 | AP12: -0.30399605 | AQ12: 6.1534717 | AR12: 5.9809746 | AS12: 6.1006316 | AT12: 6.2095422 | AU12: 6.3209996 | AV12: 6.43446 | AW12: 6.5499859 | AX12: 6.667614 | AY12: 6.7873828 | AZ12: 6.9093315 | BA12: 7.0334999 | BB12: 7.1599286 | BC12: 7.288659 | BD12: 7.4197332 | BE12: 7.5531942 | BF12: 7.6890855 | BG12: 7.8274517 | BH12: 0
D13: Rs Lakhs/MW | E13: =SUM(G13:BH13) -> 104.92967 | F13: =NPV($F$1,G13:BH13) -> 29.638217 | G13: 3.4805073 | H13: 4.0605918 | I13: 6.721328 | J13: 1.2552625 | K13: 1.7331672 | L13: 3.7462436 | M13: 2.5790374 | N13: 2.5966967 | O13: 2.5626958 | P13: 2.531153 | Q13: 2.4997036 | R13: 2.4684548 | S13: 2.4374055 | T13: 2.4065597 | U13: 2.3760282 | V13: 2.3455986 | W13: 2.3153897 | X13: 2.2853993 | Y13: 2.2556317 | Z13: 2.2260909 | AA13: 2.1967812 | AB13: 2.1677067 | AC13: 2.1388717 | AD13: 2.1102807 | AE13: 2.081938 | AF13: 2.0538483 | AG13: 2.026016 | AH13: 1.9984461 | AI13: 1.9711431 | AJ13: 1.9441121 | AK13: 2.0707733 | AL13: 2.0361223 | AM13: 2.0103733 | AN13: 1.9844574 | AO13: 1.9588637 | AP13: -0.050666009 | AQ13: 1.0255786 | AR13: 0.99682909 | AS13: 1.0167719 | AT13: 1.0349237 | AU13: 1.0534999 | AV13: 1.07241 | AW13: 1.0916643 | AX13: 1.111269 | AY13: 1.1312305 | AZ13: 1.1515552 | BA13: 1.17225 | BB13: 1.1933214 | BC13: 1.2147765 | BD13: 1.2366222 | BE13: 1.2588657 | BF13: 1.2815143 | BG13: 1.3045753 | BH13: 0
B15: E = A - B | C15: Increased Cost due to IDC & Interest Payment | D15: Rs Cr. | E15: =SUM(G15:BH15) -> -23.17877 | F15: =NPV($F$1,G15:BH15) -> -8.4724861 | G15: =G3-G6 -> -0.11215312 | H15: =H3-H6 -> -0.1308453 | I15: =I3-I6 -> -0.2879414 | J15: =J3-J6 -> -2.7381575 | K15: =K3-K6 -> -1.1641184 | L15: =L3-L6 -> -1.2552253 | M15: =M3-M6 -> -1.1574698 | N15: =N3-N6 -> -1.1187593 | ... BH15: =BH3-BH6 -> 0
D16: Rs Lakhs/MW | E16: =SUM(G16:BH16) -> -3.8631284 | F16: =NPV($F$1,G16:BH16) -> -1.412081 | G16: =G4-G7 -> -0.018692186 | H16: =H4-H7 -> -0.02180755 | I16: =I4-I7 -> -0.047990233 | J16: =J4-J7 -> -0.45635958 | K16: =K4-K7 -> -0.19401973 | L16: =L4-L7 -> -0.20920422 | M16: =M4-M7 -> -0.19291163 | N16: =N4-N7 -> -0.18645988 | ... BH16: =BH4-BH7 -> 0
B18: F = A - C | C18: Increased Cost due to IDC & Interest Payment | D18: Rs Cr. | E18: =SUM(G18:BH18) -> 5.5599253 | F18: =NPV($F$1,G18:BH18) -> -5.349785 | G18: =G3-G9 -> -0.11215312 | H18: =H3-H9 -> -0.1308453 | I18: =I3-I9 -> -0.2879414 | J18: =J3-J9 -> -2.4102919 | K18: =K3-K9 -> -0.86108275 | L18: =L3-L9 -> -0.94311581 | M18: =M3-M9 -> -0.83787537 | N18: =N3-N9 -> -0.79126274 | ... BH18: =BH3-BH9 -> 0
D19: Rs Lakhs/MW | E19: =SUM(G19:BH19) -> 0.92665422 | F19: =NPV($F$1,G19:BH19) -> -0.89163084 | G19: =G4-G10 -> -0.018692186 | H19: =H4-H10 -> -0.02180755 | I19: =I4-I10 -> -0.047990233 | J19: =J4-J10 -> -0.40171532 | K19: =K4-K10 -> -0.14351379 | L19: =L4-L10 -> -0.15718597 | M19: =M4-M10 -> -0.1396459 | N19: =N4-N10 -> -0.13187712 | ... BH19: =BH4-BH10 -> 0
B21: G = A - D | C21: Increased Cost due to IDC & Interest Payment | D21: Rs Cr. | E21: =SUM(G21:BH21) -> 34.298621 | F21: =NPV($F$1,G21:BH21) -> -2.2270839 | G21: =G3-G12 -> -0.11215312 | H21: =H3-H12 -> -0.1308453 | I21: =I3-I12 -> -0.2879414 | J21: =J3-J12 -> -2.0824263 | K21: =K3-K12 -> -0.55804711 | L21: =L3-L12 -> -0.63100627 | M21: =M3-M12 -> -0.51828098 | N21: =N3-N12 -> -0.46376619 | ... BH21: =BH3-BH12 -> 0
D22: Rs Lakhs/MW | E22: =SUM(G22:BH22) -> 5.7164368 | F22: =NPV($F$1,G22:BH22) -> -0.37118066 | G22: =G4-G13 -> -0.018692186 | H22: =H4-H13 -> -0.02180755 | I22: =I4-I13 -> -0.047990233 | J22: =J4-J13 -> -0.34707105 | K22: =K4-K13 -> -0.093007851 | L22: =L4-L13 -> -0.10516771 | M22: =M4-M13 -> -0.086380163 | N22: =N4-N13 -> -0.077294366 | ... BH22: =BH4-BH13 -> 0

Sheet Capex
E1: Cost (Rs per unit) | I1: Total Cost | J1: Cost per MW
A2: Infrastructure | C2: Unit | D2: Unit | E2: Base Price | G2: Misc | H2: Net Price | I2: Rs lakh | J2: Rs Lakh /MW
A3: Land Cost
A4: Land | B4: Govt Land | C4: Hectare | D4: =SUMIF($B$81:$B$96,$B4,$D$81:$D$96) -> 58.87 | E4: =IF(D4=0,0,SUMIF($B$81:$B$96,$B4,$I$81:$I$96)/SUMIF($B$81:$B$96,$B4,$D$81:$D$96)*10^5) -> 289665.02 | H4: =SUM(E4:G4) -> 289665.02 | I4: =IF($K4="No",0,D4*H4/10^5) -> 170.5258 | J4: =ROUND(I4/Inputs!$E$3,2) -> 0.28 | K4: Yes
A5: Land | B5: Private Land | C5: Hectare | D5: =SUMIF($B$81:$B$96,$B5,$D$81:$D$96) -> 0 | E5: =IF(D5=0,0,SUMIF($B$81:$B$96,$B5,$I$81:$I$96)/SUMIF($B$81:$B$96,$B5,$D$81:$D$96)*10^5) -> 0 | H5: =SUM(E5:G5) -> 0 | I5: =IF($K5="No",0,D5*H5/10^5) -> 0 | J5: =ROUND(I5/Inputs!$E$3,2) -> 0 | K5: Yes
A6: Land Total | B6: Sub-total | D6: =SUM(D4:D5) -> 58.87 | H6: =ROUND(I6*10^5/D6,0) -> 289665 | I6: =SUM(I4:I5) -> 170.5258 | J6: =SUM(J4:J5) -> 0.28 | M6: =34% -> 0.34 | N6: 0.33 | O6: 0.33 | R6: =M6*$I6 -> 57.978772 | S6: =N6*$I6 -> 56.273514 | T6: =O6*$I6 -> 56.273514
A7: Other Cost | H7: =SUM(E7:G7) -> 0 | I7: =IF($K7="No",0,D7*H7/10^5) -> 0 | J7: =ROUND(I7/Inputs!$E$3,2) -> 0
A8: Land Total | B8: Total | D8: =D6+D7 -> 58.87 | H8: =H6+H7 -> 289665 | I8: =I6+I7 -> 170.5258 | J8: =ROUND(I8/Inputs!$E$3,2) -> 0.28
A10: Road and associated infrastructure
A11: Road length - 5.5 metre | C11: kM | D11: =D70 -> 8.75 | E11: =110*10^5 -> 11000000 | F11: 0 | G11: 0 | H11: =SUM(E11:G11) -> 11000000 | I11: =IF($K11="No",0,D11*H11/10^5) -> 962.5 | J11: =ROUND(I11/Inputs!$E$3,2) -> 1.6
A12: Road length - 3.75 metre | C12: kM | D12: =D76 -> 20.8 | E12: =75*10^5 -> 7500000 | F12: 0 | G12: 0 | H12: =SUM(E12:G12) -> 7500000 | I12: =IF($K12="No",0,D12*H12/10^5) -> 1560 | J12: =ROUND(I12/Inputs!$E$3,2) -> 2.6
A13: Drainage | C13: kM | D13: 0 | E13: =75*10^5 -> 7500000 | F13: 0 | G13: 0 | H13: =SUM(E13:G13) -> 7500000 | I13: =IF($K13="No",0,D13*H13/10^5) -> 0 | J13: =ROUND(I13/Inputs!$E$3,2) -> 0
A14: Roads & Drainage Cost | B14: Total | D14: =SUM(D11:D13) -> 29.55 | H14: =ROUND(I14*10^5/D14,0) -> 8536379 | I14: =SUM(I11:I13) -> 2522.5 | J14: =SUM(J11:J13) -> 4.2 | M14: 0.1 | N14: 0.45 | O14: 0.45 | R14: =M14*$I14 -> 252.25 | S14: =N14*$I14 -> 1135.125 | T14: =O14*$I14 -> 1135.125
A15: Buildings & Civil structures
A16: Building & Civil Structures | C16: Hectare | D16: 0 | E16: 1200000 | F16: 0 | G16: 0 | H16: =SUM(E16:G16) -> 1200000 | I16: =IF($K16="No",0,D16*H16/10^5) -> 0 | J16: =ROUND(I16/Inputs!$E$3,2) -> 0
A17: Water Infrastruture Cost | C17: Rs Lakh | D17: =IF(Inputs!$H$2=1,2,IF(Inputs!$H$2=2,2,4)) -> 4 | E17: 500000 | F17: 0 | G17: 0 | H17: =SUM(E17:G17) -> 500000 | I17: =IF($K17="No",0,D17*H17/10^5) -> 20 | J17: =ROUND(I17/Inputs!$E$3,2) -> 0.03
A18: Storage Area | C18: Hectare | D18: 0 | E18: 1200000 | F18: 0 | G18: 0 | H18: =SUM(E18:G18) -> 1200000 | I18: =IF($K18="No",0,D18*H18/10^5) -> 0 | J18: =ROUND(I18/Inputs!$E$3,2) -> 0
A19: Building & Civil | B19: Total | D19: 0 | H19: =IF(D19=0,0,ROUND(I19*10^5/D19,0)) -> 0 | I19: =SUM(I16:I18) -> 20 | J19: =SUM(J16:J18) -> 0.03 | M19: 1 | R19: =M19*$I19 -> 20 | S19: =N19*$I19 -> 0 | T19: =O19*$I19 -> 0
A21: Substation
A22: Transformer (33/220kV) | B22: 110 MVA | C22: MW | D22: =Inputs!F122 -> 8 | E22: =5.5*10^7 -> 55000000 | F22: 0 | G22: 0 | H22: =SUM(E22:G22) -> 55000000 | I22: =IF($K22="No",0,D22*H22/10^5) -> 4400 | J22: =ROUND(I22/Inputs!$E$3,2) -> 7.33
A23: Bays - Incoming | B23: 33 kV | C23: Nos | D23: =Inputs!F123+Inputs!F124 -> 36 | E23: =0.8*10^7 -> 8000000 | F23: 0 | G23: 0 | H23: =SUM(E23:G23) -> 8000000 | I23: =IF($K23="No",0,D23*H23/10^5) -> 2880 | J23: =ROUND(I23/Inputs!$E$3,2) -> 4.8
A24: Bays - Outgoing | B24: 220 kV | C24: Nos | D24: =Inputs!F125+Inputs!F126+Inputs!F127 -> 14 | E24: =3*10^7 -> 30000000 | F24: 0 | G24: 0 | H24: =SUM(E24:G24) -> 30000000 | I24: =IF($K24="No",0,D24*H24/10^5) -> 4200 | J24: =ROUND(I24/Inputs!$E$3,2) -> 7 | L24: Also include 220kV Bay at STU S/S
A25: Control & Communication | C25: Nos | D25: =Inputs!F128 -> 2 | E25: =100*10^5 -> 10000000 | F25: 0 | G25: 0 | H25: =SUM(E25:G25) -> 10000000 | I25: =IF($K25="No",0,D25*H25/10^5) -> 200 | J25: =ROUND(I25/Inputs!$E$3,2) -> 0.33
A26: Sub-station | B26: Total | D26: =(IF(Inputs!$H$2=1,1,IF(Inputs!$H$2=2,1,2))) -> 2 | H26: =ROUND(I26*10^5/D26,0) -> 584000000 | I26: =SUM(I22:I25) -> 11680 | J26: =SUM(J22:J25) -> 19.46 | M26: 0.25 | N26: 0.45 | O26: 0.3 | R26: =M26*$I26 -> 2920 | S26: =N26*$I26 -> 5256 | T26: =O26*$I26 -> 3504
A28: Transmission Line
